Workbook
Name TC: CAPEX!$D$3

Sheet Glosario
A1: Acrónimo / Término | B1: Significado | C1: Explicación para terceros
A2: FTE | B2: Full-Time Equivalent | C2: Unidad que representa a una persona trabajando tiempo completo. Se usa para normalizar costos de personal, incluso si hay turnos o personal parcial.
A3: PUE | B3: Power Usage Effectiveness | C3: Indicador de eficiencia energética del data center. PUE = Energía total del sitio / Energía de TI. Un PUE de 1.2 indica alta eficiencia.
A4: PM | B4: Preventive Maintenance | C4: Mantenimiento preventivo programado para evitar fallas en equipos críticos como UPS, chillers, plantas eléctricas y sistemas contra incendio.
A5: OPEX | B5: Operating Expenditure | C5: Gastos operativos recurrentes necesarios para operar el data center (energía, personal, mantenimiento, servicios).
A6: CAPEX | B6: Capital Expenditure | C6: Inversión inicial en infraestructura, equipos y construcción del data center.
A7: UPS | B7: Uninterruptible Power Supply | C7: Sistema de respaldo eléctrico que mantiene energizados los equipos durante fallas o transiciones a plantas de emergencia.
A8: BMS | B8: Building Management System | C8: Plataforma de monitoreo y control de sistemas mecánicos y eléctricos del edificio.
A9: EPMS | B9: Electrical Power Monitoring System | C9: Sistema especializado para monitorear la distribución eléctrica y calidad de energía del data center.
A10: CRAH | B10: Computer Room Air Handler | C10: Equipo de enfriamiento que maneja aire frío en salas de servidores.
A11: CDU | B11: Coolant Distribution Unit | C11: Unidad de distribución de refrigerante, común en sistemas de liquid cooling para IA.
A12: NOC | B12: Network Operations Center | C12: Centro de monitoreo 24/7 de redes y sistemas TI. En este modelo se asume que no existe NOC dedicado.
... A18: MW_Base | B18: 1MW | C18: Capacidad de referencia (en megawatts) utilizada para normalizar los costos operativos del data center y expresarlos en métricas unitarias como MXN/kW-mes. No representa potencia adicional ni consumo real, sino una base matemática para análisis comparativo y escalabilidad del modelo.

Sheet Inputs
A1: Parámetro | B1: Unidades | C1: Valor | D1: Unidad / Nota
A2: IT_Load_MW | B2: MW | C2: 1 | D2: MW (carga TI)
A3: PUE | B3: Factor | C3: 1.2 | D3: Total Facility Load / IT Load
A4: Horas_año | B4: hrs | C4: 8760 | D4: horas en un año
A5: Tarifa kWh | B5: USD | C5: ='Bloque IBD'!R8 -> 0.11860465 | D5: USD/kWh (ajustable)
A6: Factor_prestaciones | B6: % | C6: 0.3 | D6: 30% sobre sueldos base
A7: Guardias_y_HE_% | B7: % | C7: 0.1 | D7: 10% extra sobre sueldos (si aplica)
A8: MW_base | B8: MW | C8: 1 | D8: MW para normalizar MXN/kW-mes
A9: KW a MW | B9: Conversion | C9: 1000
A10: TC MXN/USD | B10: Conversion | C10: 17.2
A12: Métrica derivada | C12: Fórmula | D12: Resultado
A13: Facility_Load_MW | B13: MW | C13: =C2*C3 -> 1.2 | D13: Carga Total
A14: Consumo_kWh_año | B14: kWh | C14: =C2*C3*C9*C4 -> 10512000 | D14: Consumo anual en kWh
A15: Costo energia x kWh | B15: USD | C15: =C5 -> 0.11860465 | D15: =C13*C5 -> 0.14232558
A16: Costo_energía año | B16: USD | C16: =C14*C15 -> 1246772.1 | D16: =C14/12 -> 876000

Sheet S&U
B3: Concept | C3: Unit | D3: Metric
B4: LTV GPUs | C4: % | D4: 0.8
B5: I/Y GPUs | C5: % | D5: 0.12
B6: Tenor GPUs | C6: yrs | D6: 3
B7: Monthly payment GPUs | C7: PMT | D7: =PMT(D5/12,D6*12,-D16) -> 1005641.6
B8: LTV DC CAPEX | C8: % | D8: 0.8
B9: I/Y DC CAPEX | C9: % | D9: 0.08
B10: Tenor DC CAPEX | C10: yrs | D10: 10
B11: Monthly payment DC CAPEX | C11: PMT | D11: =PMT(D9/12,D10*12,-D17) -> 70551.36
B12: DSRA | C12: months | D12: 0
B13: EPC Financing | C13: % | D13: 0.1
B15: Sources | C15: Description | D15: Ammount | F15: Uses | G15: Description | H15: Ammount
B16: Debt Financing GPUs | C16: Financing ammount for GPUs | D16: =H16*D4 -> 30277361 | F16: GPUs | G16: Dell or Supermicro w/NVIDIA B300 (HPC Compute) | H16: =Hoja1!E45 -> 37846701
B17: Debt Financing DC CAPEX | C17: Financing ammount for DC CAPEX | D17: =D8*H17 -> 5814947.6 | F17: AUXILIARY CAPEX | G17: Cooling, electrical, plumbing, telecom, etc. | H17: =SUM(H18:H29) -> 7268684.5
B18: Fermaca Equity | C18: Equity from within | D18: 3000000 | F18: SISTEMA DE GENERACIÓN DE RESPALDO (GENERADORES) | G18: Aux DC CAPEX | H18: =Hoja1!E8 -> 933813.57
B19: New Investor Equity | C19: New Investor needs | D19: =H41-D20-D18-D17-D16 -> 8420151.7 | F19: INTERRUPTOR DE TRANSFERENCIA AUTOMÁTICA (ATS) | G19: Aux DC CAPEX | H19: =Hoja1!E10 -> 192932.87
B20: EPC Financing | C20: 10% EPC financing | D20: =D13*(H31+H32) -> 90000 | F20: TRANSFORMADOR PRINCIPAL | G20: Aux DC CAPEX | H20: =Hoja1!E12 -> 222740.82
F21: UPS | G21: Aux DC CAPEX | H21: =Hoja1!E14 -> 1050171.8
B22: Total Sources | D22: =SUM(D16:D20) -> 47602460 | F22: BANCO DE BATERÍAS | G22: Aux DC CAPEX | H22: =Hoja1!E16 -> 402506.94
F23: TABLERO DE MEDIA TENSIÓN | G23: Aux DC CAPEX | H23: =Hoja1!E18 -> 168563.46
D24: =D22=H41 -> TRUE | F24: SWITCHGEAR | G24: Aux DC CAPEX | H24: =Hoja1!E20 -> 544324.95
F25: SISTEMA DE REFRIGERACIÓN PARA LOS GABINETES MODULARES TIPO CONTENEDOR (CHILLERS) | G25: Aux DC CAPEX | H25: =Hoja1!E21 -> 1565349.3
F26: Telecom | G26: Aux DC CAPEX | H26: =Hoja1!E25 -> 460244.5
F27: SEGURIDAD | G27: Aux DC CAPEX | H27: =Hoja1!E31 -> 303759.5
F28: DDC (Gabinetes) | G28: Aux DC CAPEX | H28: =Hoja1!E34 -> 1218276.8
F29: Procura y Obra Gestor | G29: Aux DC CAPEX | H29: =Hoja1!E46 -> 206000
F30: Non Fineaceable CAPEX | G30: Project development, engineering, construction, non detachable | H30: =SUM(H31:H36) -> 1838847.4
F31: Engineering | G31: Engineering | H31: 300000
F32: Construction | G32: FDO Construction | H32: 600000
F33: Commissioning | G33: Tests | H33: 110000
F34: CFE Commitments | G34: CFE quote for capacity increase | H34: =(1043900+40000+3870100)/20 -> 247700
F35: Bcysa Feasibility & Development contract | G35: BCYSA Quote | H35: 250000
F36: Bcysa Owners Engineer | G36: BCYSA Quote | H36: =0.04*(H17+H31+H32+H33) -> 331147.38 | J36: Contingency | K36: 0.07
F37: Permits and Studies | G37: Local permits and structural studies | H37: 10000 | J37: Subtotal | K37: =(H17+H30+H37)*1 -> 9117531.8
F38: Contingency | G38: 7% contigency | H38: =K37*K36 -> 638227.23
F39: DSCA of 3 months | G39: Construction reserve account | H39: =D7*D12 -> 0
F41: Total Uses | H41: =H16+H17+H30+H37+H38+H39 -> 47602460

Sheet Hoja1
A2: CATALOGO DE EQUIPOS PRINCIPALES
A4: PROYECTO | B4: Data Center 1MW IT en el edificio de Fermaca
B5: DESCRIPCIÓN | C5: UNIDAD | D5: CANTIDAD | E5: Precio Promedio*
B6: SUMINISTRO E INSTALACION DE EQUIPOS PRICIPALES
A7: 1 | B7: SISTEMA DE GENERACIÓN DE RESPALDO (GENERADORES)
A8: 1.1 | B8: SUMINISTRO E INSTALACIÓN GENERADOR DE EMERGENCIA IMPULSADO CON MOTOR A DIESEL CAPACIDAD 600 KW/750KVA, EN PRIME PARA USO EN DATA CENTER ,F.P. 0.8 TENSIÓN DE SALIDA 480V, 60 HZ, VELOCIDAD 1800 RPM, CON INTERRUPTOR ELECTROMAGNÉTICO PARA GENERADOR A PIE DE EQUIPO DE 1500A DE MARCO, INCLUYE PANEL DE CONTROL DEL GRUPO ELECTRÓGENO MONTADO EN CUBÍCULO DE ACERO PINTADO, DE ACUERDO CON LOS ESTÁNDARES DE FÁBRICA, ADECUADO PARA ARRANQUE / PARADA, OPERACIÓN DE FALLA DE RED TOTALMENTE AUTOMÁTICA, EL PANEL SE INSTALARÁ EN EL CONTENEDOR AL LADO DEL GENERADOR DIÉSEL, CONTENEDOR INSONORO HC ISO DE 40 PIES ADECUADO PARA INSTALACIÓN EN EXTERIORES PROVISTO DE VENTILACIÓN EN SISTEMA DE SALIDA, SISTEMA DE ESCAPE. NIVEL SONORO MÁXIMO APROX. 84 DB (A) +/- 2 DB A 1 METRO (CONDICIONES AL INTERIOR DE EDIFCIOS) CON CONTENEDOR DE DIÉSEL INCORPORADO A LA CABINA, TIPO SUBBASE DE DOBLE PARED PARA SUMINISTRO DE 24 HRS. Y BANCO DE RESISTESTENCIA LIMITADORA EN NEUTRO. | C8: PZA | D8: 2 | E8: 933813.57
A9: 2 | B9: INTERRUPTOR DE TRANSFERENCIA AUTOMÁTICA (ATS)
A10: 2.1 | B10: SUMINISTRO E INSTALACIÓN DE TRANSFERENCIA AUTOMÁTICA, CONFORMADO POR UN CONTACTO PRINCIPAL, SEGUIDO POR RECEPCIÓN DE ACOMETIDA PRINCIPAL Y DOS (2) BUSES PARA CADA GENERADOR, CAPACIDAD EN BARRAS PARA 2500A, TENSIÓN DE OPERACIÓN 480V, 60 HZ, CON CELDAS DE PROTECCIÓN EN CADA BUS A TRAVÉS DE INTERRUPTORES ELECTROMAGNÉTICO PARA CADA BUS DE 2500A DE MARCO, INCLUYE PANEL DE CONTROL DE LA TRANSFERENCIA, TABLERO AUTO SOPORTADO, PINTADO, DE ACUERDO CON LOS ESTÁNDARES DE FÁBRICA, CON MODOS DE OPERACIÓN MANUAL, NO AUTOMÁTICO Y AUTOMÁTICO. CON JUEGO DE ZAPATAS MECÁNICAS. ASISTENCIA TÉCNICA PARA INSTALACIÓN, PRE-ARRANQUE Y PUESTA EN MARCHA. CAPACITACIÓN PARA OPERACIÓN Y MANTENIMIENTO | C10: PZA | D10: 1 | E10: 192932.87
A11: 3 | B11: TRANSFORMADOR PRINCIPAL
A12: 3.1 | B12: TRANSFORMADOR DE POTENCIA DE MEDIA, TENSIÓN CAPACIDAD 1500 KVA, DEVANADOS DE COBRE, CONEXIÓN DELTA ESTRELLA, ELEVACIÓN. DE TEMPERATURA 80-115¬C RELACIÓN 23 KV - 0.48 KV, ENFRIAMIENTO AN, TIPO SECO EN RESINA EPÓXICA. ASISTENCIA TÉCNICA PARA INSTALACIÓN, PRE-ARRANQUE Y PUESTA EN MARCHA. CAPACITACIÓN PARA OPERACIÓN Y MANTENIMIENTO | C12: PZA | D12: 1 | E12: 222740.82
A13: 4 | B13: UPS
A14: 4.1 | B14: SUMINISTRO E INSTALACIÓN DE UPS9000 DE 1250KVA EN CONFIGURACION MMS, 480V DE ENTRADA, 480V DE SALIDA, 3F-3H+T, 60Hz, INCLUYE TARJETA DE COMUNICACIÓN IS-UNITY-DP. ASISTENCIA TÉCNICA PARA INSTALACIÓN, PRE-ARRANQUE Y PUESTA EN MARCHA. CAPACITACIÓN PARA OPERACIÓN Y MANTENIMIENTO | C14: PZA | D14: 2 | E14: 1050171.8
A15: 5 | B15: BANCO DE BATERÍAS
A16: 5.1 | B16: SUMINISTRO E INSTALACIÓN SISTEMA DE BATERIAS DE LITIO ENERGY CORE LI5, CADA SISTEMA ESTA FORMADO POR 7 BANCOS DE BATERIAS PARA RESPALDAR UNA CARGA DE 1187KW DURANTE 9.8 MINUTOS, CADA BANCO CUENTA CON SU DESCONECTADOR Y BMS. ASISTENCIA TÉCNICA PARA INSTALACIÓN, PRE-ARRANQUE Y PUESTA EN MARCHA. CAPACITACIÓN PARA OPERACIÓN Y MANTENIMIENTO | C16: PZA | D16: 2 | E16: 402506.94
A17: 6 | B17: TABLERO DE MEDIA TENSIÓN
A18: 6.1 | B18: SUMINISTRO E INSTALACIÓN TABLERO DE MEDIA TENSIÓN TIPO METAL CLAD, CLASE 25 KV, 60HZ, CON INTERRUPTORES DE POTENCIA EN VACÍO, INCLUYE RELEVADORES DE PROTECCIÓN Y MEDIDOR MULTIFUNCIÓN UNO (1) INTERRUPTORES DE POTENCIA EN VACIO PRINCIPAL PARA ACOMETIDA UNO (1) JUEGO DE CUCHILLAS DESCONECTADORAS ASISTENCIA TÉCNICA PARA INSTALACIÓN, PRE-ARRANQUE Y PUESTA EN MARCHA. CAPACITACIÓN PARA OPERACIÓN Y MANTENIMIENTO | C18: PZA | D18: 1 | E18: 168563.46
A19: 7 | B19: SWITCHGEAR
A20: 7.1 | B20: SUMINISTRO TABLERO DE BAJA TENSIÓN TIPO SWITCHGEAR, GABINETE NEMA 1A, TENSIÓN 480 V, 3 F, 3 H, 60 HZ, COMPUESTO POR: UNO (1) INTERRUPTOR ELECTROMAGNÉTICO PRINCIPALES PARA ACOMETIDA DE 2000 A, 65 KA, FUNCIONES DE PROTECCIÓN 50/51, 59, 25, 27, 86, (5)TP´S REL. 480 / 120 V, 1.2Z, (3) TC´S REL. 5000/5 PRECISIÓN C400 PARA PROTECCIÓN, (3) TC´S REL. 5000/5 PRECISIÓN 0.3B 0.1-01.8 PARA MEDICIÓN(A, V, KW, KWH, VAR, FP, THD) OCHO (8) INTERRUPTORES ELECTROMAGNÉTICOS 500 A, 65 KA, FUNCIONES DE PROTECCIÓN 50/51, 59, 25, 27, 86. (8) TP´S REL. 480 / 120 V, (8) TC´S REL. 2000/5 PRECISIÓN C400 PARA PROTECCIÓN, (8) TC´S REL. 2000/5 PRECISIÓN 0.4B0.4 PARA MEDICIÓN (A, V, KW, KWH, VAR, FP, THD) CUATRO (4) INTERRUPTORES ELECTROMAGNÉTICOS 400 A, 65 KA, FUNCIONES DE PROTECCIÓN 50/51, 59, 25, 27, 86. (8) TP´S REL. 480 / 120 V, (8) TC´S REL. 2000/5 PRECISIÓN C400 PARA PROTECCIÓN, (8) TC´S REL. 2000/5 PRECISIÓN 0.4B0.4 PARA MEDICIÓN (A, V, KW, KWH, VAR, FP, THD) ASISTENCIA TÉCNICA PARA INSTALACIÓN, PRE-ARRANQUE Y PUESTA EN MARCHA. CAPACITACIÓN PARA OPERACIÓN Y MANTENIMIENTO | C20: PZA | D20: 1 | E20: 544324.95
A21: 8 | B21: SISTEMA DE REFRIGERACIÓN PARA LOS GABINETES MODULARES TIPO CONTENEDOR (CHILLERS) | E21: 1565349.3
A22: 8.1 | B22: SUMINISTRO E INSTALACIÓN DE CHILLERS PARA EL CIRCUITO DE ENFRIAMIENTO, HACIA LOS GABINETES MODULARES TIPO CONTENEDOR TIENEN UN COMPARTIMIENTO EN LA PARTE SUPERIOR DONDE ESTÁ ALOJADO EL INTERCAMBIADOR DE CALOR CON UNA POTENCIA ELÉCTRICA NOMINAL DE 10 KW CADA UNO PARA ABATIR LA CARGA TÉRMICA GENERADA POR LOS SERVIDORES, LOS CUALES PRESENTAN UNA CARGA ELÉCTRICA DE 58 KW, LA CAPACIDAD DEL CHILLER DEBEERÁ DE SER APRXIMADAMENTE DE 400 TR. ASISTENCIA TÉCNICA PARA INSTALACIÓN, PRE-ARRANQUE Y PUESTA EN MARCHA. CAPACITACIÓN PARA OPERACIÓN Y MANTENIMIENTO | C22: LOTE | D22: 2
A23: 8.2 | B23: BOMBAS DE AGUA HELADA (DE SER NECESARIO): BANCOS DE BOMBAS PRIMARIAS Y SECUNDARIAS EN CONFIGURACIÓN REDUNDANTE (N+1), CON VARIADORES DE FRECUENCIA, TABLEROS DE CONTROL Y ACCESORIOS HIDRÁULICOS | C23: LOTE | D23: 1
A24: 8.3 | B24: DEPÓSITO DE AGUA HELADA (DE SER NECESARIO): TANQUE AISLADO DE CAPACIDAD SUFICIENTE PARA GARANTIZAR 10 MINUTOS DE AUTONOMÍA EN CASO DE INDISPONIBILIDAD TEMPORAL DE LOS CHILLERS. | C24: LOTE | D24: 1
A25: 10 | B25: TELECOM | E25: 460244.5
A26: 10.1 | B26: SUMINISTRO E INSTALACIÓN DE SISTEMA DE CCTV INCLUYE CÁMARAS, EQUIPO DE GRABACIÓN, MONITOREO Y ALMACENAMIENTO. | C26: LOTE | D26: 1
A27: 10.2 | B27: SUMINISTRO E INSTALACIÓN DEL SISTEMA DE VOZ Y DATOS, INCLUYE SWITCHES, ROUTERS, FIREWALLS, EQUIPO DE TELEFÓNIA. | C27: LOTE | D27: 1
A28: 10.3 | B28: SUMINISTRO E INSTACIÓN DEL SISTEMA DE CONTROL DE ACCESO INCLUYE EQUIPO DE ADMINISTRACIÓN, CONTROLADORES DE PUERTAS, LECTORES DE TARJETAS DOBLE AUTENTIFICACIÓN Y ACCESORIOS. | C28: LOTE | D28: 1
A29: 10.4 | B29: SUNINISTRO E INSTALCION DE CABLEADO ESTRUCTURADO INCLUYE ACCESORIOS Y CANALIZACIONES. | C29: LOTE | D29: 1
A30: 10.5 | B30: SUMINISTRO, INSTALACIÓN Y PREPARACIÓN PARA LA CONCENTRACIÓN DE SEÑALES HACIA EL BMS / DCIM. | C30: LOTE | D30: 1
A31: 11 | B31: SEGURIDAD | E31: 303759.5
A32: 11.1 | B32: SUMINISTRO E INSTALACIÓN DEL SISTEMA DE SUPRESIÓN TIPO FLUORO K., INCLUYE ASISTENCIA TÉCNICA PARA INSTALACIÓN, PRE-ARRANQUE Y PUESTA EN MARCHA. CAPACITACIÓN PARA OPERACIÓN Y MANTENIMIENTO | C32: LOTE | D32: 1
A33: 11.2 | B33: SUMINISTRO E INSTALACIÓN DEL SISTEMA DE DETECCIÓN (CONVENCIONAL), ALARMAS, ESTACIONES MANUALES, EXTINTORES Y LETREROS DE SEÑALIZACIÓN. | C33: LOTE | D33: 1
A34: 12 | B34: MDC (Gabinetes) | E34: 1218276.8
A35: 12.1 | B35: 415v - 52U, 36W, up to 85kw air with mounting rails | C35: PZA | D35: 20
A36: 12.2 | B36: Brass Plumbing Kit | C36: PZA | D36: 20
A37: 12.3 | B37: DCIM Analytics Controller | C37: PZA | D37: 10
A38: 12.4 | B38: DCIM License per cabinet per year | C38: PZA | D38: 20
A39: 12.5 | B39: DCIM Software Training | C39: PZA | D39: 1
A40: 12.6 | B40: Fire Suppression | C40: PZA | D40: 20
A41: 12.7 | B41: Preventative Maintenance per year | C41: PZA | D41: 20
A42: 12.8 | B42: S-Line Series Implementation & Commissioning | C42: PZA | D42: 20
...

Sheet CAPEX
A1: CAPEX PROYECTO FDO
A3: Tipo de Cambio Mxn/USD | D3: =Inputs!C10 -> 17.2
A5: Other Indirect
A6: Concepto | B6: Unidad | C6: Cantidad | D6: Precio Unitario USD | E6: Importe USD | F6: Comentarios
A7: Bank comission | B7: Servicio | C7: 1 | E7: =C7*D7 -> 0 | F7: TBD
A8: Legal | B8: Servicio | C8: 1 | E8: =C8*D8 -> 0 | F8: Dependerá de si es un proyect Finance o no
A9: Subtotal | E9: =+SUM(E7:E8) -> 0
A11: EPC
A12: Ingenieria de detalle | B12: Servicios | C12: 1 | D12: =ATN!H11 -> 155874 | E12: =D12*C12 -> 155874 | F12: Ingenieria elabrada por el EPC.
A13: Refuerzos estructurales | B13: Lote y Servicios | C13: 1 | E13: =D13*C13 -> 0 | F13: Por recibir análisis del proveedor y posteriormente se cotizará con EPC
A14: Estructura para equipo Chiller al lado del edificio | B14: Lote y Servicios | C14: 1 | D14: =ATN!D16+ATN!H16 -> 393745 | E14: =D14*C14 -> 393745 | F14: Soportes para Chillers
A15: Demoliciones (Instalaciones) | B15: Servicios | C15: 1 | D15: =ATN!D17+ATN!H17 -> 187647 | E15: =D15*C15 -> 187647 | F15: Demolición de paredes y gimnasio.
A16: Civil Planta Baja (Instalaciones) | B16: Servicios | C16: 1 | D16: =ATN!D18+ATN!H18 -> 415874 | E16: =D16*C16 -> 415874 | F16: Adecuaciones para equipos criticos
A17: Civil Sotano (Instalaciones) | B17: Servicios | C17: 1 | D17: =ATN!D19+ATN!H19 -> 165287 | E17: =D17*C17 -> 165287 | F17: Adecuaciones para transformador, plantas de emergencia, tanques de combustible (contencion antiderrames)
A18: Obra eléctrica MT (Instalaciones) | B18: Servicios | C18: 1 | D18: =ATN!D21+ATN!H21 -> 95874 | E18: =D18*C18 -> 95874 | F18: Cableado de CFE a la subestacion, SW gear
A19: Obra eléctrica BT (Instalaciones) | B19: Servicios | C19: 1 | D19: =ATN!D22+ATN!H22 -> 929373 | E19: =D19*C19 -> 929373 | F19: Cableado desde el transformador al SWgear, tierras, Iluminación
A20: Obra mecánica (Instalaciones) | B20: Servicios | C20: 1 | D20: =ATN!D23+ATN!H23 -> 815367 | E20: =D20*C20 -> 815367 | F20: Ducterias, cabelados etc para llegar al MDC.
A21: Isonorizacion del cuarto plantas de emergencia (Suministro e Instalaciones) | B21: Servicios | C21: 1 | D21: =ATN!D24+ATN!H24 -> 128957 | E21: =D21*C21 -> 128957 | F21: Cajas acústicas para generadores
A22: =ATN!A12 -> Comisionamiento | B22: Servicios | C22: 1 | D22: =ATN!H12 -> 105684 | E22: =D22*C22 -> 105684 | F22: Pruebas y puesta en marcha de equipos y sistemas
A23: =ATN!A13 -> Equipo de pruebas CX | B23: Servicios | C23: 1 | D23: =ATN!H13 -> 25000 | E23: =D23*C23 -> 25000 | F23: Renta de equipos para pruebas
A24: Subtotal EPC | E24: =+SUM(E12:E23) -> 3418682
A27: Procura Critical Equipment (EPC o BSD) f
A28: MV Driescher (seccionador electrico) | B28: pza y servicios | C28: =ATN!B27 -> 1 | D28: =ATN!D27+ATN!H27 -> 55698 | E28: =C28*D28 -> 55698 | F28: Subtestación hipercompacta
A29: MV Transformer 1.5 MVA | B29: pza y servicios | C29: =ATN!B28 -> 1 | D29: =ATN!D28+ATN!H28 -> 196874 | E29: =C29*D29 -> 196874 | F29: Provision de transformador
A30: Generator 1250W, Escape exterior y tanque de diesel | B30: pza y servicios | C30: =ATN!B29 -> 2 | D30: =ATN!D29+ATN!H29 -> 415874 | E30: =C30*D30 -> 831748 | F30: Para certificación se requeriran dos generadores
A31: LV Swithgear | B31: pza y servicios | C31: =ATN!B30 -> 1 | D31: =ATN!D30+ATN!H30 -> 333327 | E31: =C31*D31 -> 333327 | F31: Función de ATS (autonatic trasnfer Switch)
A32: UPS IT 1000 kva GVX1000K1000NGS | B32: pza y servicios | C32: =ATN!B31 -> 2 | D32: =ATN!D31+ATN!H31 -> 565247 | E32: =C32*D32 -> 1130494 | F32: Baterias de litio y bypass de emparelamiento por capacidad
A33: PDUS 500KVA | B33: pza y servicios | C33: =ATN!B32 -> 0 | D33: =ATN!D32+ATN!H32 -> 78140 | E33: =C33*D33 -> 0 | F33: Incluidos en el MDC
A34: CRAH Inrow CW 12.5 TR | B34: pza y servicios | C34: =ATN!B33 -> 0 | D34: =ATN!D33+ATN!H33 -> 35254 | E34: =C34*D34 -> 0 | F34: Incluidos en el MDC
A35: CHILER WATER 340 TR | B35: pza y servicios | C35: =ATN!B34 -> 2 | D35: =ATN!D34+ATN!H34 -> 589658 | E35: =C35*D35 -> 1179316 | F35: Incluye deñositios de agua
A36: CDU 0750 MOTIVAIR | B36: servicios | C36: =ATN!B35 -> 0 | D36: =ATN!D35+ATN!H35 -> 165874 | E36: =C36*D36 -> 0 | F36: Incluidos en el MDC
A37: CRAH ELECTRIC ROOMS, 3TR. | B37: pza y servicios | C37: 7 | D37: =ATN!D36+ATN!H36 -> 20859 | E37: =C37*D37 -> 146013 | F37: Cuarto de baterias, UPS, equipos, MMR.
A38: Equipo menor | B38: servicios | C38: 1 | D38: =ATN!D37+ATN!H37 -> 85987 | E38: =C38*D38 -> 85987 | F38: LV Panelboards, LV TRs, etc.
A39: Subtotal | E39: =+SUM(E28:E38) -> 3959457
A42: Special Systems f
A43: Sistema de monitoreo de Infraestructura | B43: Lote y Servicios | C43: 1 | D43: =ATN!D40+ATN!H40 -> 185874 | E43: =C43*D43 -> 185874
A44: Cuarto Telecom MMR | B44: Lote y Servicios | C44: 1 | D44: =ATN!D41+ATN!H41 -> 45254 | E44: =C44*D44 -> 45254 | F44: Se tendrá un solo cuarto de carriers (5 racks) + MMR (2 racks)
A45: CCTV | B45: Lote y Servicios | C45: 1 | D45: =ATN!D42+ATN!H42 -> 65254 | E45: =C45*D45 -> 65254
A46: Control de Acceso | B46: Lote y Servicios | C46: 1 | D46: =ATN!D43+ATN!H43 -> 52358.5 | E46: =C46*D46 -> 52358.5
A47: Vesda | B47: Lote y Servicios | C47: 1 | D47: =ATN!D44+ATN!H44 -> 230254 | E47: =C47*D47 -> 230254 | F47: Sistema inteligente de deteccion de particulas en el sitio.
...

Sheet OPEX
A1: Rubro | B1: Elemento / Área | C1: Equipo / Puesto | D1: Unidad | E1: Cantidad | F1: Costo Unitario (MXN/mes) | G1: MXN/mes | H1: MXN/año | J1: MXN/kW-mes | K1: Notas | M1: Resumen | N1: OPEX MXN/mes | O1: OPEX MXN/año | P1: MXN/kW-mes
N2: =G60 -> 2657529 | O2: =H60 -> 31890348 | P2: =N2/(Inputs!$C$8*1000) -> 2657.529
N3: OPEX USD/mes | O3: OPEX USD/año | P3: USD/kW-mes
N4: =G62 -> #REF! | O4: =H62 -> #REF! | P4: =N4/(Inputs!$C$8*1000) -> #REF!
A5: ENERGIA | F5: =SUM(F7:F7) -> 0 | G5: =SUM(G7:G7) -> 0 | H5: =SUM(H7:H7) -> 0 | I5: =SUM('OPEX (2)'!I6) -> 1246772.1 | J5: =SUM(J7:J7) -> 0
A6: ENERGÍA | B6: Electricidad | C6: Energía total (IT 1MW, PUE 1.2) | D6: mes | E6: 1 | K6: Costo mensual calculado en Inputs (energía).
B7: Gas | K7: Costo de gas natural, si aplica
A9: O&M INFRA | F9: =SUM(F10:F21) -> 424000 | G9: =SUM(G10:G21) -> 454000 | H9: =SUM(H10:H21) -> 5448000 | I9: =H9/TC -> 316744.19 | J9: =SUM(J10:J21) -> 454
B10: Energía crítica | C10: UPS (PM + refacciones) | D10: equipo | E10: 1 | F10: 90000 | G10: =E10*F10 -> 90000 | H10: =G10*12 -> 1080000 | I10: =H10/TC -> 62790.698 | J10: =G10/(Inputs!C8*1000) -> 90 | K10: Contrato anual prorrateado + refacciones menores. | M10: Maintanance Every three years
B11: Energía crítica | C11: Baterías (pruebas + mantenimiento) | D11: banco | E11: 1 | F11: 35000 | G11: =E11*F11 -> 35000 | H11: =G11*12 -> 420000 | I11: =H11/TC -> 24418.605 | J11: =G11/(Inputs!C8*1000) -> 35 | K11: Sin reemplazo mayor; considerar reserva de CAPEX por vida útil. | M11: inspection each year
B12: Energía crítica | C12: Plantas de emergencia (PM) | D12: planta | E12: 2 | F12: 30000 | G12: =E12*F12 -> 60000 | H12: =G12*12 -> 720000 | I12: =H12/TC -> 41860.465 | J12: =G12/(Inputs!C8*1000) -> 60 | K12: Incluye pruebas; excluye overhaul mayor.
B13: Energía crítica | C13: Combustible pruebas / logística | D13: mes | E13: 1 | F13: 12000 | G13: =E13*F13 -> 12000 | H13: =G13*12 -> 144000 | I13: =H13/TC -> 8372.093 | J13: =G13/(Inputs!C8*1000) -> 12 | K13: Pruebas y reposición por ejercicios.
B14: Distribución | C14: Tableros/Interruptores (PM) | D14: sitio | E14: 1 | F14: 18000 | G14: =E14*F14 -> 18000 | H14: =G14*12 -> 216000 | I14: =H14/TC -> 12558.14 | J14: =G14/(Inputs!C8*1000) -> 18 | K14: Termografía, torque, limpieza técnica.
B15: Enfriamiento | C15: Chillers/CDU/CRAH (PM + químicos) | D15: sitio | E15: 1 | F15: 140000 | G15: =E15*F15 -> 140000 | H15: =G15*12 -> 1680000 | I15: =H15/TC -> 97674.419 | J15: =G15/(Inputs!C8*1000) -> 140 | K15: Incluye agua tratada/anticorrosivos si aplica.
B16: Enfriamiento | C16: Bombas/valvulas/ductos (PM) | D16: sitio | E16: 1 | F16: 15000 | G16: =E16*F16 -> 15000 | H16: =G16*12 -> 180000 | I16: =H16/TC -> 10465.116 | J16: =G16/(Inputs!C8*1000) -> 15 | K16: Refacciones menores.
B17: Seguridad | C17: Sistema contra incendio (detección + supresión) | D17: sitio | E17: 1 | F17: 30000 | G17: =E17*F17 -> 30000 | H17: =G17*12 -> 360000 | I17: =H17/TC -> 20930.233 | J17: =G17/(Inputs!C8*1000) -> 30 | K17: Mantenimientos y recargas menores.
B18: Monitoreo | C18: BMS/EPMS (soporte + licencias) | D18: sitio | E18: 1 | F18: 40000 | G18: =E18*F18 -> 40000 | H18: =G18*12 -> 480000 | I18: =H18/TC -> 27906.977 | J18: =G18/(Inputs!C8*1000) -> 40 | K18: Sin NOC; solo plataforma y mantenimiento.
B19: Infraestructura | C19: Sistema de tierras / pararrayos (PM) | D19: sitio | E19: 1 | F19: 6000 | G19: =E19*F19 -> 6000 | H19: =G19*12 -> 72000 | I19: =H19/TC -> 4186.0465 | J19: =G19/(Inputs!C8*1000) -> 6 | K19: Mediciones anuales prorrateadas.
B20: Infraestructura | C20: MDC | D20: equipo | E20: 1 | G20: =E20*F20 -> 0 | H20: =G20*12 -> 0 | I20: =H20/TC -> 0 | J20: =G20/(Inputs!C8*1000) -> 0
B21: Infraestructura | C21: Sellos / pasillos (mantenimiento) | D21: sitio | E21: 1 | F21: 8000 | G21: =E21*F21 -> 8000 | H21: =G21*12 -> 96000 | I21: =H21/TC -> 5581.3953 | J21: =G21/(Inputs!C8*1000) -> 8 | K21: Ajustes y consumibles.
I22: =H22/TC -> 0
A23: PERSONAL | F23: =SUM(F24:F34) -> 555800 | G23: =SUM(G24:G34) -> 673400 | H23: =SUM(H24:H34) -> 8080800 | I23: =H23/TC -> 469813.95 | J23: =SUM(J24:J34) -> 673.4
A24: PERSONAL FACILITIES | B24: Operación | C24: Técnico Facilities (turnos) - Sueldo base | D24: FTE | E24: 3 | F24: 42000 | G24: =E24*F24 -> 126000 | H24: =G24*12 -> 1512000 | I24: =H24/TC -> 87906.977 | J24: =G24/(Inputs!C8*1000) -> 126 | K24: Sueldo base mensual por FTE (editable). | M24: Personel | N24: Try to get them on in construction so they really soak in the information
A25: PERSONAL FACILITIES | B25: Operación | C25: Técnico Facilities - Cargas (prestaciones + guardias) | D25: FTE | E25: 3 | F25: =42000*(Inputs!C6+Inputs!C7) -> 16800 | G25: =E25*F25 -> 50400 | H25: =G25*12 -> 604800 | I25: =H25/TC -> 35162.791 | J25: =G25/(Inputs!C8*1000) -> 50.4 | K25: Se calcula sobre el sueldo base (Inputs). | N25: Can cross train into DC operations | O25: 12hrs shift or on call | P25: On call bonus
A26: PERSONAL FACILITIES | B26: Gestión | C26: Facility Manager - Sueldo base | D26: FTE | E26: 1 | F26: 75000 | G26: =E26*F26 -> 75000 | H26: =G26*12 -> 900000 | I26: =H26/TC -> 52325.581 | J26: =G26/(Inputs!C8*1000) -> 75 | K26: Sueldo base mensual (editable). | M26: Mid level electrician | N26: Can cross train into DC operations | O26: 12hrs shift or on call | P26: On call bonus
A27: PERSONAL FACILITIES | B27: Gestión | C27: Facility Manager - Cargas (prestaciones + guardias) | D27: FTE | E27: 1 | F27: =75000*(Inputs!C6+Inputs!C7) -> 30000 | G27: =E27*F27 -> 30000 | H27: =G27*12 -> 360000 | I27: =H27/TC -> 20930.233 | J27: =G27/(Inputs!C8*1000) -> 30 | K27: Se calcula sobre el sueldo base (Inputs). | M27: Third party electrical contact or contractor in case our 2 engineers are not available
A28: PERSONAL IT | B28: Network | C28: Ingeniero de Red - Sueldo base | D28: FTE | E28: 1 | F28: 90000 | G28: =E28*F28 -> 90000 | H28: =G28*12 -> 1080000 | I28: =H28/TC -> 62790.698 | J28: =G28/(Inputs!C8*1000) -> 90 | K28: Operación LAN/DC fabric, FW, routing, interconexión. | M28: DDC and HH Support tickets
A29: PERSONAL IT | B29: Network | C29: Ingeniero de Red - Cargas (prestaciones + guardias) | D29: FTE | E29: 1 | F29: =90000*(Inputs!C6+Inputs!C7) -> 36000 | G29: =E29*F29 -> 36000 | H29: =G29*12 -> 432000 | I29: =H29/TC -> 25116.279 | J29: =G29/(Inputs!C8*1000) -> 36 | K29: Se calcula sobre el sueldo base (Inputs). | M29: Data Center Operations Personnel
A30: PERSONAL IT | B30: Plataforma IA | C30: Sysadmin / Cluster Admin (Linux, Slurm/K8s) | D30: FTE | E30: 1 | F30: 100000 | G30: =E30*F30 -> 100000 | H30: =G30*12 -> 1200000 | I30: =H30/TC -> 69767.442 | J30: =G30/(Inputs!C8*1000) -> 100 | K30: Operación de servidores IA/GB300, drivers, images, orchestration. | M30: Data Center Network Engineer
A31: PERSONAL IT | B31: Plataforma IA | C31: Cluster Admin - Cargas (prestaciones + guardias) | D31: FTE | E31: 1 | F31: =100000*(Inputs!C6+Inputs!C7) -> 40000 | G31: =E31*F31 -> 40000 | H31: =G31*12 -> 480000 | I31: =H31/TC -> 27906.977 | J31: =G31/(Inputs!C8*1000) -> 40 | K31: Se calcula sobre el sueldo base (Inputs). | M31: Upstream electrical (CFE)
A32: PERSONAL IT | B32: Soporte HW | C32: Técnico HW (hands-on) - Sueldo base | D32: FTE | E32: 1 | F32: 65000 | G32: =E32*F32 -> 65000 | H32: =G32*12 -> 780000 | I32: =H32/TC -> 45348.837 | J32: =G32/(Inputs!C8*1000) -> 65 | K32: Swap de partes, cableado, inventario, RMA.
A33: PERSONAL IT | B33: Soporte HW | C33: Técnico HW - Cargas (prestaciones + guardias) | D33: FTE | E33: 1 | F33: =65000*(Inputs!C6+Inputs!C7) -> 26000 | G33: =E33*F33 -> 26000 | H33: =G33*12 -> 312000 | I33: =H33/TC -> 18139.535 | J33: =G33/(Inputs!C8*1000) -> 26 | K33: Se calcula sobre el sueldo base (Inputs). | M33: Plan for security within the building for offtakers
A34: PERSONAL IT | B34: Seguridad | C34: Soporte SOC externo (retainer) - opcional | D34: mes | E34: 1 | F34: 35000 | G34: =E34*F34 -> 35000 | H34: =G34*12 -> 420000 | I34: =H34/TC -> 24418.605 | J34: =G34/(Inputs!C8*1000) -> 35 | K34: No es NOC; retainer mínimo para incident response.
M35: Use DDC system - NOC might be over doing it
A36: SERVICIOS | F36: =SUM(F37:F43) -> 429155 | G36: =SUM(G37:G43) -> 960129 | H36: =SUM(H37:H43) -> 11521548 | I36: =H36/TC -> 669857.44 | J36: =SUM(J37:J43) -> 960.129 | M36: Use DCIM for DDC
A37: SERVICIOS | B37: Telecom | C37: Internet/Transit (2 enlaces 1xGB) | D37: enlace | E37: 2 | F37: 26100 | G37: =E37*F37 -> 52200 | H37: =G37*12 -> 626400 | I37: =H37/TC -> 36418.605 | J37: =G37/(Inputs!C8*1000) -> 52.2 | K37: Por negociar | M37: HH has a support channel for technical stuff - HH helps us understand our devices as best as possible
A38: SERVICIOS | B38: Telecom | C38: Internet/Transit (2 enlaces 100xGB) | D38: enlace | E38: 3 | F38: 252437 | G38: =E38*F38 -> 757311 | H38: =G38*12 -> 9087732 | I38: =H38/TC -> 528356.51 | J38: =G38/(Inputs!C8*1000) -> 757.311 | K38: Por negociar y homologar soluciones | M38: Tim, Miky and Bojan for ongoing brokkr and platform support.
A39: SERVICIOS | B39: Telecom | C39: /25 | D39: mes | E39: 1 | F39: 34618 | G39: =E39*F39 -> 34618 | H39: =G39*12 -> 415416 | I39: =H39/TC -> 24152.093 | J39: =G39/(Inputs!C8*1000) -> 34.618 | K39: Por negociar
A40: SERVICIOS | B40: Seguridad física | C40: Guardias (24/7) + CCTV (OPEX) | D40: mes | E40: 1 | F40: 15000 | G40: =E40*F40 -> 15000 | H40: =G40*12 -> 180000 | I40: =H40/TC -> 10465.116 | J40: =G40/(Inputs!C8*1000) -> 15 | K40: no contempla precio de guardias. Solo CCTV
A41: SERVICIOS | B41: Limpieza | C41: Limpieza especializada DC | D41: mes | E41: 1 | F41: 25000 | G41: =E41*F41 -> 25000 | H41: =G41*12 -> 300000 | I41: =H41/TC -> 17441.86 | J41: =G41/(Inputs!C8*1000) -> 25 | K41: Limpieza técnica. Lo realiza el personal de Facilities
...

Sheet OPEX (2)
A1: Rubro | B1: Elemento / Área | C1: Equipo / Puesto | D1: Unidad | E1: Cantidad | F1: Costo Unitario (MXN/mes) | G1: MXN/mes | H1: MXN/año | I1: USD/año | J1: MXN/kW-mes | K1: Notas | M1: Resumen | N1: OPEX MXN/mes | O1: OPEX MXN/año | P1: MXN/kW-mes
N2: =G42 -> 3521020 | O2: =H42 -> 46452240 | P2: =N2/(Inputs!$C$8*1000) -> 3521.02
N3: OPEX USD/mes | O3: OPEX USD/año | P3: USD/kW-mes
N4: =G44 -> 204710.47 | O4: =H44 -> 2700711.6 | P4: =N4/(Inputs!$C$8*1000) -> 204.71047
A5: ENERGIA | F5: =SUM(F6) -> 1787040 | G5: =SUM(G6) -> 1787040 | H5: =SUM(H6) -> 21444480 | I5: =SUM(I6) -> 1246772.1 | J5: =SUM(J6) -> 1787.04
A6: ENERGÍA | B6: Electricidad | C6: Energía total (IT 1MW, PUE 1.2) | D6: mes | E6: 1 | F6: =(Inputs!C16*TC)/12 -> 1787040 | G6: =OPEX!E6*F6 -> 1787040 | H6: =G6*12 -> 21444480 | I6: =H6/TC -> 1246772.1 | J6: =G6/(Inputs!C8*1000) -> 1787.04 | K6: Costo mensual calculado en Inputs (energía).
A7: O&M INFRA | F7: =SUM(F8:F19) -> 424000 | G7: =SUM(G8:G19) -> 454000 | H7: =SUM(H8:H19) -> 5448000 | I7: =H7/TC -> 316744.19 | J7: =SUM(J8:J19) -> 454
B8: Energía crítica | C8: UPS (PM + refacciones) | D8: equipo | E8: 1 | F8: 90000 | G8: =E8*F8 -> 90000 | H8: =G8*12 -> 1080000 | I8: =H8/TC -> 62790.698 | J8: =G8/(Inputs!C8*1000) -> 90 | K8: Contrato anual prorrateado + refacciones menores.
B9: Energía crítica | C9: Baterías (pruebas + mantenimiento) | D9: banco | E9: 1 | F9: 35000 | G9: =E9*F9 -> 35000 | H9: =G9*12 -> 420000 | I9: =H9/TC -> 24418.605 | J9: =G9/(Inputs!C8*1000) -> 35 | K9: Sin reemplazo mayor; considerar reserva de CAPEX por vida útil.
B10: Energía crítica | C10: Plantas de emergencia (PM) | D10: planta | E10: 2 | F10: 30000 | G10: =E10*F10 -> 60000 | H10: =G10*12 -> 720000 | I10: =H10/TC -> 41860.465 | J10: =G10/(Inputs!C8*1000) -> 60 | K10: Incluye pruebas; excluye overhaul mayor.
B11: Energía crítica | C11: Combustible pruebas / logística | D11: mes | E11: 1 | F11: 12000 | G11: =E11*F11 -> 12000 | H11: =G11*12 -> 144000 | I11: =H11/TC -> 8372.093 | J11: =G11/(Inputs!C8*1000) -> 12 | K11: Pruebas y reposición por ejercicios.
B12: Distribución | C12: Tableros/Interruptores (PM) | D12: sitio | E12: 1 | F12: 18000 | G12: =E12*F12 -> 18000 | H12: =G12*12 -> 216000 | I12: =H12/TC -> 12558.14 | J12: =G12/(Inputs!C8*1000) -> 18 | K12: Termografía, torque, limpieza técnica.
B13: Enfriamiento | C13: Chillers/CDU/CRAH (PM + químicos) | D13: sitio | E13: 1 | F13: 140000 | G13: =E13*F13 -> 140000 | H13: =G13*12 -> 1680000 | I13: =H13/TC -> 97674.419 | J13: =G13/(Inputs!C8*1000) -> 140 | K13: Incluye agua tratada/anticorrosivos si aplica.
B14: Enfriamiento | C14: Bombas/valvulas/ductos (PM) | D14: sitio | E14: 1 | F14: 15000 | G14: =E14*F14 -> 15000 | H14: =G14*12 -> 180000 | I14: =H14/TC -> 10465.116 | J14: =G14/(Inputs!C8*1000) -> 15 | K14: Refacciones menores.
B15: Seguridad | C15: Sistema contra incendio (detección + supresión) | D15: sitio | E15: 1 | F15: 30000 | G15: =E15*F15 -> 30000 | H15: =G15*12 -> 360000 | I15: =H15/TC -> 20930.233 | J15: =G15/(Inputs!C8*1000) -> 30 | K15: Mantenimientos y recargas menores.
B16: Monitoreo | C16: BMS/EPMS (soporte + licencias) | D16: sitio | E16: 1 | F16: 40000 | G16: =E16*F16 -> 40000 | H16: =G16*12 -> 480000 | I16: =H16/TC -> 27906.977 | J16: =G16/(Inputs!C8*1000) -> 40 | K16: Sin NOC; solo plataforma y mantenimiento.
B17: Infraestructura | C17: Sistema de tierras / pararrayos (PM) | D17: sitio | E17: 1 | F17: 6000 | G17: =E17*F17 -> 6000 | H17: =G17*12 -> 72000 | I17: =H17/TC -> 4186.0465 | J17: =G17/(Inputs!C8*1000) -> 6 | K17: Mediciones anuales prorrateadas.
B18: Infraestructura | C18: MDC | D18: equipo | E18: 1 | G18: =E18*F18 -> 0 | H18: =G18*12 -> 0 | I18: =H18/TC -> 0 | J18: =G18/(Inputs!C8*1000) -> 0
B19: Infraestructura | C19: Sellos / pasillos (mantenimiento) | D19: sitio | E19: 1 | F19: 8000 | G19: =E19*F19 -> 8000 | H19: =G19*12 -> 96000 | I19: =H19/TC -> 5581.3953 | J19: =G19/(Inputs!C8*1000) -> 8 | K19: Ajustes y consumibles.
A20: PERSONNEL | F20: =SUM(F21:F23) -> 205000 | G20: =SUM(G21:G23) -> 410000 | H20: =SUM(H21:H23) -> 4920000 | I20: =H20/TC -> 286046.51 | J20: =SUM(J21:J23) -> 410
A21: PERSONAL FACILITIES | B21: Operación | C21: Master Electrician | D21: FTE | E21: 2 | F21: 85000 | G21: =E21*F21 -> 170000 | H21: =G21*12 -> 2040000 | I21: =H21/TC -> 118604.65 | J21: =G21/(Inputs!C8*1000) -> 170 | K21: Sueldo base mensual contemplando costo total de la compañía
A22: PERSONAL FACILITIES | B22: Operación | C22: Mid Level Electricians | D22: FTE | E22: 2 | F22: 60000 | G22: =E22*F22 -> 120000 | H22: =G22*12 -> 1440000 | I22: =H22/TC -> 83720.93 | J22: =G22/(Inputs!C8*1000) -> 120 | K22: Sueldo base mensual contemplando costo total de la compañía
A23: PERSONAL FACILITIES | B23: Gestión | C23: Network Engineers | D23: FTE | E23: 2 | F23: 60000 | G23: =E23*F23 -> 120000 | H23: =G23*12 -> 1440000 | I23: =H23/TC -> 83720.93 | J23: =G23/(Inputs!C8*1000) -> 120 | K23: Sueldo base mensual contemplando costo total de la compañía
A24: FSCA (Back Office) | F24: =SUM(F25) -> 67000 | G24: =SUM(G25:G25) -> 67000 | H24: =G24*12 -> 804000 | I24: =H24/TC -> 46744.186 | J24: =SUM(J25:J25) -> 67
A25: FSCA | B25: Back Office | C25: Admin | D25: mes | E25: 1 | F25: 67000 | G25: =F25*E25 -> 67000 | H25: =G25*12 -> 804000 | I25: =H25/TC -> 46744.186 | J25: =G25/(Inputs!C8*1000) -> 67
A26: SERVICIOS | B26: Consumibles | C26: PPE, herramientas, etiquetas, consumibles | D26: mes | E26: 1 | F26: 6000 | G26: =E26*F26 -> 6000 | H26: =G26*12 -> 72000 | I26: =H26/TC -> 4186.0465 | J26: =G26/(Inputs!C3*1000) -> 5 | K26: Consumibles de operación.
A27: Telecom | F27: =SUM(F28:F30) -> 654980 | G27: =SUM(G28:G30) -> 654980 | H27: =SUM(H28:H30) -> 7859760 | I27: =H27/TC -> 456962.79 | J27: =SUM(J28:J30) -> 654.98
A28: Telecom | B28: Telecom | C28: Internet/Transit (2 enlaces 1xGB) | D28: enlace | E28: 1 | F28: 39780 | G28: =E28*F28 -> 39780 | H28: =G28*12 -> 477360 | I28: =H28/TC -> 27753.488 | J28: =G28/(Inputs!C8*1000) -> 39.78 | K28: Por negociar
A29: Telecom | B29: Telecom | C29: Internet/Transit (2 enlaces 100xGB) | D29: enlace | E29: 1 | F29: 560000 | G29: =E29*F29 -> 560000 | H29: =G29*12 -> 6720000 | I29: =H29/TC -> 390697.67 | J29: =G29/(Inputs!C8*1000) -> 560 | K29: Por negociar y homologar soluciones
A30: Telecom | B30: Telecom | C30: /25 | D30: mes | E30: 1 | F30: 55200 | G30: =E30*F30 -> 55200 | H30: =G30*12 -> 662400 | I30: =H30/TC -> 38511.628 | J30: =G30/(Inputs!C8*1000) -> 55.2 | K30: Por negociar
A31: Seguros | F31: =SUM(F32) -> 350000 | G31: =SUM(G32) -> 350000 | H31: =SUM(H32) -> 4200000 | I31: =H31/TC -> 244186.05 | J31: =SUM(J32) -> 350
A32: Seguros | B32: Seguros | C32: Seguro Propiedad (OEM+MDc)+ RC + Operación | D32: mes | E32: 1 | F32: 350000 | G32: =E32*F32 -> 350000 | H32: =G32*12 -> 4200000 | I32: =H32/TC -> 244186.05 | J32: =G32/(Inputs!C8*1000) -> 350 | K32: Prorrateo mensual; depende de sumas aseguradas.
A33: Hydra Host | F33: =SUM(F34:F34) -> 40000 | G33: =SUM(G34:G34) -> 40000 | H33: =SUM(H34:H34) -> 480000 | I33: =H33/TC -> 27906.977 | J33: =SUM(J34:J35) -> 145
A34: Hydra Host | B34: Brokkr Platform | C34: Bare Metal Platform | D34: mes | E34: 1 | F34: 40000 | G34: =E34*F34 -> 40000 | H34: =G34*12 -> 480000 | I34: =H34/TC -> 27906.977
A35: SOPORTE OEM | F35: =SUM(F36:F37) -> 145000 | G35: =SUM(G36:G37) -> 145000 | H35: =SUM(H36:H37) -> 1740000 | I35: =H35/TC -> 101162.79 | J35: =SUM(J36:J37) -> 145
A36: SOPORTE OEM | B36: Servidores IA | C36: Soporte OEM GPU/Servidor (NBD/4h) - prorrateo | D36: mes | E36: 1 | F36: 120000 | G36: =E36*F36 -> 120000 | H36: =G36*12 -> 1440000 | I36: =H36/TC -> 83720.93 | J36: =G36/(Inputs!C8*1000) -> 120 | K36: Depende del contrato con Dell/OEM; ajustar a cotización.
A37: SOPORTE OEM | B37: Servidores IA | C37: Reserva RMA/Partes críticas (fans, etc) | D37: mes | E37: 1 | F37: 25000 | G37: =E37*F37 -> 25000 | H37: =G37*12 -> 300000 | I37: =H37/TC -> 17441.86 | J37: =G37/(Inputs!C8*1000) -> 25 | K37: Buffer de partes; puede ser inventario (CAPEX) o gasto.
A39: NOC | F39: =SUM(F40:F41) -> 70000 | G39: =SUM(G40:G41) -> 70000 | H39: =SUM(H40:H41) -> 840000 | I39: =H39/TC -> 48837.209 | J39: =SUM(J40:J41) -> 70
A40: Telecom | B40: Telecom | C40: 2 enlaces de Internet empresarial / dedicado (backup + OOB). Troncales de voz / SIP / softphones | D40: mes | E40: 1 | F40: 50000 | G40: =E40*F40 -> 50000 | H40: =G40*12 -> 600000 | I40: =H40/TC -> 34883.721 | J40: =G40/(Inputs!C8*1000) -> 50
A41: Otros | B41: Personal, Admin, mobiliario | C41: mobiliario, Capacitacion | D41: mes | E41: 1 | F41: 20000 | G41: =E41*F41 -> 20000 | H41: =G41*12 -> 240000 | I41: =H41/TC -> 13953.488 | J41: =G41/(Inputs!C8*1000) -> 20
...

Sheet OPEX NOTAS
B2: Proovedor | C2: Item | D2: Costo Anual USD | E2: Comentario
B3: FSCA | C3: Contabilidad, RH, CPP, CPC, etc. | D3: TBD
B4: NOC | C4: O&M NOC | D4: 1000000
B5: Murguia | C5: Seguro operativo | D5: 380000 | E5: Seguro de los equipos, edificos, responsabilidad civil

Sheet Pass-Through IBD
C3: Cargos | D3: Concepto | E3: Unitario | F3: 45658 | G3: 45689 | H3: 45717 | I3: 45748 | J3: 45778 | K3: 45809 | L3: 45839 | M3: 45870 | N3: 45901 | O3: 45931 | P3: 45962 | Q3: 45992 | R3: Anual
B4: Regulada | C4: Fijo | D4: Cargo de Capacidad | E4: MXN/kWh | F4: 0.66 | G4: 0.73 | H4: 0.66 | I4: 0.66 | J4: 0.63 | K4: 0.64 | L4: 0.62 | M4: 0.61 | N4: 0.63 | O4: 0.61 | P4: 0.63 | Q4: 0.61 | R4: 0.61
B5: Negociable | C5: Variable | D5: Energía Asociada a la CAP | E5: MXN/kWh | F5: 0.76 | G5: 0.61 | H5: 0.66 | I5: 0.53 | J5: 0.55 | K5: 0.5 | L5: 0.52 | M5: 0.49 | N5: 0.5 | O5: 0.52 | P5: 0.6 | Q5: 0.55 | R5: 0.54
B6: Regulada | C6: Variable | D6: Congestión | E6: MXN/kWh | F6: 0.21 | G6: 0.15 | H6: 0.15 | I6: 0.3 | J6: 0.33 | K6: 0.13 | L6: 0.1 | M6: 0.09 | N6: 0.17 | O6: 0.13 | P6: 0.16 | Q6: 0.15 | R6: 0.16
B7: Regulada | C7: Variable | D7: Cargos Regulados y MEM | E7: MXN/kWh | F7: 0.54 | G7: 0.54 | H7: 0.54 | I7: 0.54 | J7: 0.54 | K7: 0.54 | L7: 0.54 | M7: 0.54 | N7: 0.54 | O7: 0.54 | P7: 0.54 | Q7: 0.54 | R7: 0.51
B8: Negociable | C8: Variable | D8: Cargos CELs | E8: MXN/kWh | F8: 0.06 | G8: 0.06 | H8: 0.06 | I8: 0.05 | J8: 0.05 | K8: 0.05 | L8: 0.05 | M8: 0.05 | N8: 0.05 | O8: 0.05 | P8: 0.05 | Q8: 0.05 | R8: 0.05
C9: Total | D9: Costo All In Energia | E9: MXN | F9: =SUM(F4:F8) -> 2.23 | G9: =SUM(G4:G8) -> 2.09 | H9: =SUM(H4:H8) -> 2.07 | I9: =SUM(I4:I8) -> 2.08 | J9: =SUM(J4:J8) -> 2.1 | K9: =SUM(K4:K8) -> 1.86 | L9: =SUM(L4:L8) -> 1.83 | M9: =SUM(M4:M8) -> 1.78 | ... R9: =SUM(R4:R8) -> 1.87
C10: Total | D10: Costo All In Energia | E10: USD | F10: =F9/Inputs!$C$10 -> 0.12965116 | G10: =G9/Inputs!$C$10 -> 0.12151163 | H10: =H9/Inputs!$C$10 -> 0.12034884 | I10: =I9/Inputs!$C$10 -> 0.12093023 | J10: =J9/Inputs!$C$10 -> 0.12209302 | K10: =K9/Inputs!$C$10 -> 0.10813953 | L10: =L9/Inputs!$C$10 -> 0.10639535 | M10: =M9/Inputs!$C$10 -> 0.10348837 | ... R10: =R9/Inputs!$C$10 -> 0.10872093
F11: =0.07*17.5 -> 1.225

Sheet Bloque IBD
C2: Cargos | D2: Concepto | E2: Unitario | F2: 45658 | G2: 45689 | H2: 45717 | I2: 45748 | J2: 45778 | K2: 45809 | L2: 45839 | M2: 45870 | N2: 45901 | O2: 45931 | P2: 45962 | Q2: 45992 | R2: Anual
B3: Regulados y Negociables | C3: Fijo / Variable | D3: Energía + Fijo Potencia + CEL | E3: MXN/kWh | F3: 1.48 | G3: 1.65 | H3: 1.49 | I3: 1.48 | J3: 1.42 | K3: 1.43 | L3: 1.39 | M3: 1.38 | N3: 1.41 | O3: 1.38 | P3: 1.41 | Q3: 1.36 | R3: 1.38
B4: Negociable | C4: Variable | D4: Energía de Sobre Consumo | E4: MXN/kWh | F4: 0.04 | G4: $- | H4: 0.04 | I4: $- | J4: 0.04 | K4: $- | L4: 0.05 | M4: 0.04 | N4: $- | O4: 0.04 | P4: $- | Q4: 0.06 | R4: 0.03
B5: Regulada | C5: Variable | D5: Congestión | E5: MXN/kWh | F5: 0.2 | G5: 0.15 | H5: 0.14 | I5: 0.3 | J5: 0.33 | K5: 0.13 | L5: 0.1 | M5: 0.09 | N5: 0.17 | O5: 0.12 | P5: 0.16 | Q5: 0.16 | R5: 0.16
B6: Regulada | C6: Variable | D6: Capacidad | E6: MXN/kWh | F6: 0.49 | G6: 0.49 | H6: 0.49 | I6: 0.49 | J6: 0.49 | K6: 0.49 | L6: 0.49 | M6: 0.49 | N6: 0.49 | O6: 0.49 | P6: 0.49 | Q6: 0.49 | R6: 0.47
C7: Total | D7: Costo All In Energia | E7: MXN | F7: =SUM(F3:F6) -> 2.21 | G7: =SUM(G3:G6) -> 2.29 | H7: =SUM(H3:H6) -> 2.16 | I7: =SUM(I3:I6) -> 2.27 | J7: =SUM(J3:J6) -> 2.28 | K7: =SUM(K3:K6) -> 2.05 | L7: =SUM(L3:L6) -> 2.03 | M7: =SUM(M3:M6) -> 2 | ... R7: =SUM(R3:R6) -> 2.04
C8: Total | D8: Costo All In Energia | E8: USD | F8: =F7/Inputs!$C$10 -> 0.12848837 | G8: =G7/Inputs!$C$10 -> 0.13313953 | H8: =H7/Inputs!$C$10 -> 0.1255814 | I8: =I7/Inputs!$C$10 -> 0.13197674 | J8: =J7/Inputs!$C$10 -> 0.13255814 | K8: =K7/Inputs!$C$10 -> 0.11918605 | L8: =L7/Inputs!$C$10 -> 0.11802326 | M8: =M7/Inputs!$C$10 -> 0.11627907 | ... R8: =R7/Inputs!$C$10 -> 0.11860465

Sheet Exp PreOP
B3: Viajes | C3: Localidad | D3: Dias | E3: Monto total
B4: DDC Solutions (SDG) | C4: San Diego, Calif | D4: 1 | E4: =8309/Inputs!C10 -> 483.0814
B5: DDCSolutions | C5: Tijuana | D5: 1 | E5: =4839/Inputs!C10 -> 281.33721
B6: Subtotal | E6: =SUM(E4:E5) -> 764.4186
B8: Gestor CFE | E8: 35000
B9: Subtotal | E9: =SUM(E8) -> 35000
B11: Personal | C11: Horas | D11: Costos Hora | E11: Costo Total
B12: Manuel Calvillo A
B13: Manuel calvillo G
B14: Santiago Miranada
B15: Mauricio Flores
B16: Subtotal | E16: =SUM(E14:E15) -> 0
B18: Gastos Notarios | E18: 44,670.00
B19: Subtotal | E19: =E18 -> 44,670.00
B21: Gastos Fsca
B22: Subtotal | E22: =SUM(E20:E21) -> 0

Sheet Generadores
C4: PLANELEC | E4: Descripción | F4: Cant. | G4: Tiempo de Entrega | H4: Precio Unit. USD | I4: Precio Total USD
E5: Planta Modelo 230G3D0820C1250 | F5: 2 | G5: 45 a 60 días | H5: 154790 | I5: =F5*H5 -> 309580
E6: Interruptor Electromagnético de 1250 amp. a pie de generador | F6: 2 | G6: 45 a 60 días | H6: 5910 | I6: =F6*H6 -> 11820
E7: Transferencia Dual Mutual de 1250 amp barras de carga de 2500 amp | F7: 1 | G7: 45 a 60 días | H7: 24870 | I7: =F7*H7 -> 24870
E8: Caseta acústica bajo techo Nivel II (78 dBa @7m) NEMA 1A | F8: 2 | G8: 45 a 60 días | H8: 17490 | I8: =F8*H8 -> 34980
E9: Resistencia de puesta a tierra | F9: 2 | G9: 45 a 60 días | H9: 4610 | I9: =F9*H9 -> 9220
H10: Total | I10: =SUM(I5:I9) -> 390470
C13: MADISA | E13: Alcance | F13: Cant. | G13: Precio
E14: Motogenerador | F14: 2 | G14: Incluido
E15: － Motogenerador CATERPILLAR modelo C27.
E16: － Potencia: 680 kWISO
E17: － Aplicación: Prime
E18: － Voltaje: 480V, frecuencia: 60 Hz, F.P.: 0.8
E19: Sistema de escape
E20: － Silenciador grado critico
E21: Comisionamiento, arranque y puesta en marcha
E22: Contenedor 30’ para motogenerador modelo C27 de 680kW, nivel de ruido estimado: 85 dB a 7m. Tanque base para combustible, 5000 LT., construcción doble pared.
E23: Sistema de detección y supresión de incendio
E24: Capacitación en sitio, máx. 10 participantes, 5 días
E25: Pruebas FAT
E26: Pruebas SAT
E27: － Tablero de fuerza y control de transferencia transición cerrada 2500 amp, 480V. | F27: 1 | G27: Incluido
E28: Total | G28: $ 622,622 USD
C32: GENERAC | E32: DESCRIPCIÓN | F32: CANT. UNIDAD | G32: Precio Unitario | H32: Subtotal
E34: 1 PLY900 | F34: 2 | G34: 241468 | H34: =F34*G34 -> 482936
E35: Planta de emergencia Automática, marca
E36: Generac 900kW nominales, 480VAC 3F 4H,
E37: 60Hz, P.F 0.8, controlador a pie de maquina
E38: DS7420, Planta modelo PLY900:
E39: Capacidad de Servicio Emergencia:
E40: - 914 kW / 1142 Kva
E41: Capacidad de Servicio Prime:
E42: - 813 kW / 1016 kVA
E43: -
E44: -POTENCIA EFECTIVA EN SITIO EN
E45: APLICACIÓN Prime: 600KW a 2240 msnm
E46: Velocidad Angular: 1,800 R.P.M
... E68: HGO, Parque Industrial Platah.
E70: 2 ATS | F70: 2 | G70: Incluido | H70: Incluido
E71: -Tablero de transferencia en transición abierta,
...

Sheet ATN
B4: CPD para cargas de trabajo de IA de alta densidad.
B6: Infraestructura (Equipamiento) | F6: Servicios e Instalaciones | J6: Gran Total
A7: Centro de cómputo TIER II (UPTIME) BCYSA-FERMACA
A8: Diseño | B8: Cantidad | C8: U.M. | D8: P.U | E8: Precio Total | F8: Cantidad | G8: U.M. | H8: P.U | I8: Precio Total
A10: Diseño conceptual | F10: 1 | G10: Serv | H10: 26984.525 | I10: =H10*F10 -> 26984.525 | J10: =I10+E10 -> 26984.525
A11: Ingenieria de Detalle | F11: 1 | G11: Serv | H11: 155874 | I11: =H11*F11 -> 155874 | J11: =I11+E11 -> 155874
A12: Comisionamiento | F12: 1 | G12: Serv | H12: 105684 | I12: =H12*F12 -> 105684 | J12: =I12+E12 -> 105684
A13: Equipo de pruebas CX | F13: 1 | G13: Serv | H13: 25000 | I13: =H13*F13 -> 25000 | J13: =I13+E13 -> 25000 | L13: RESUMEN, CDP TIER II, 1MW (PRECIO ALZADO)
E14: =SUM(E10:E13) -> 0 | I14: =SUM(I10:I13) -> 313542.53
A15: Builting Construction & Fit Out | M15: Infraestructura | N15: Serv e Inst
A16: Estructura para equipo Chiller al lado del edificio | B16: 1 | C16: Lte | D16: 210247 | E16: =D16*B16 -> 210247 | F16: 1 | G16: Serv | H16: 183498 | I16: =H16*F16 -> 183498 | J16: =I16+E16 -> 393745
A17: Demoliciones (Instalaciones) | F17: 1 | G17: Serv | H17: 187647 | I17: =H17*F17 -> 187647 | J17: =I17+E17 -> 187647 | L17: =A8 -> Diseño | M17: =E14 -> 0 | N17: =I14 -> 313542.53
A18: Civil Planta Baja (Instalaciones) | F18: 1 | G18: Serv | H18: 415874 | I18: =H18*F18 -> 415874 | J18: =I18+E18 -> 415874 | L18: =A15 -> Builting Construction & Fit Out | M18: =E25 -> 351517 | N18: =I25 -> 2967587
A19: Civil Sotano (Instalaciones) | F19: 1 | G19: Serv | H19: 165287 | I19: =H19*F19 -> 165287 | J19: =I19+E19 -> 165287 | L19: =A26 -> Misión Critical Equipment (Suministros) | M19: =E38 -> 3385602.5 | N19: =I38 -> 552995.5
A20: Sistema Piso Falso (Suministro e Instalaciones) | B20: 1 | C20: Lte | D20: 141270 | E20: =D20*B20 -> 141270 | F20: 1 | G20: Serv | H20: 45710 | I20: =H20*F20 -> 45710 | J20: =I20+E20 -> 186980 | L20: =A39 -> Special Systems (Suministros) | M20: =E47 -> 635879 | N20: =I47 -> 366650.24
A21: Obra eléctrica MT (Instalaciones) | F21: 1 | G21: Serv | H21: 95874 | I21: =H21*F21 -> 95874 | J21: =I21+E21 -> 95874 | L21: =A48 -> HYPER POD (Suministros) | M21: =E50 -> 1798367 | N21: =I50 -> 179836.7
A22: Obra eléctrica BT (Instalaciones) | F22: 1 | G22: Serv | H22: 929373 | I22: =H22*F22 -> 929373 | J22: =I22+E22 -> 929373 | L22: =A51 -> Preoperative cost (Instalaciones) | M22: =E54 -> 0 | N22: =I54 -> 15950
A23: Obra mecánica (Instalaciones) | F23: 1 | G23: Serv | H23: 815367 | I23: =H23*F23 -> 815367 | J23: =I23+E23 -> 815367
A24: Isonorizacion del cuarto plantas y louvers (Suministro e Instalaciones) | F24: 1 | G24: Serv | H24: 128957 | I24: =H24*F24 -> 128957 | J24: =I24+E24 -> 128957 | M24: =SUM(M17:M23) -> 6171365.5 | N24: =SUM(N17:N23) -> 4396562
E25: =SUM(E16:E24) -> 351517 | I25: =SUM(I16:I24) -> 2967587
A26: Misión Critical Equipment (Suministros) | L26: Subtotal, USD | M26: =M24+N24 -> 10567927
A27: MV Driescher (seccionador electrico) | B27: 1 | C27: Pza | D27: 48748 | E27: =D27*B27 -> 48748 | F27: 1 | G27: Serv | H27: 6950 | I27: =H27*F27 -> 6950 | J27: =I27+E27 -> 55698
A28: MV Transformer 1.5 MVA | B28: 1 | C28: Pza | D28: 173249.5 | E28: =D28*B28 -> 173249.5 | F28: 1 | G28: Serv | H28: 23624.5 | I28: =H28*F28 -> 23624.5 | J28: =I28+E28 -> 196874
A29: Generator 1250W, Escape exterior y tanque de diesel | B29: 2 | C29: Pza | D29: 349334 | E29: =D29*B29 -> 698668 | F29: 2 | G29: Serv | H29: 66540 | I29: =H29*F29 -> 133080 | J29: =I29+E29 -> 831748
A30: LV Swithgear | B30: 1 | C30: Pza | D30: 287762 | E30: =D30*B30 -> 287762 | F30: 1 | G30: Serv | H30: 45565 | I30: =H30*F30 -> 45565 | J30: =I30+E30 -> 333327
A31: UPS IT 1000 kva GVX1000K1000NGS | B31: 2 | C31: Pza | D31: 503722.5 | E31: =D31*B31 -> 1007445 | F31: 2 | G31: Serv | H31: 61524.5 | I31: =H31*F31 -> 123049 | J31: =I31+E31 -> 1130494
A32: PDUS 500KVA | B32: 0 | C32: Pza | D32: 75570 | E32: =D32*B32 -> 0 | F32: 0 | G32: Serv | H32: 2570 | I32: =H32*F32 -> 0 | J32: =I32+E32 -> 0
A33: CRAH Inrow CW 12.5 TR | B33: 0 | C33: Pza | D33: 31023.667 | E33: =D33*B33 -> 0 | F33: 0 | G33: Serv | H33: 4230.3333 | I33: =H33*F33 -> 0 | J33: =I33+E33 -> 0
A34: CHILER WATER 340 TR | B34: 2 | C34: Pza | D34: 532155 | E34: =D34*B34 -> 1064310 | F34: 2 | G34: Serv | H34: 57503 | I34: =H34*F34 -> 115006 | J34: =I34+E34 -> 1179316
A35: CDU 0750 MOTIVAIR | B35: 0 | C35: Pza | D35: 146786.75 | E35: =D35*B35 -> 0 | F35: 0 | G35: Serv | H35: 19087.25 | I35: =H35*F35 -> 0 | J35: =I35+E35 -> 0
A36: CRAH ELECTRIC ROOMS, 3TR. | B36: 6 | C36: Pza | D36: 17570 | E36: =D36*B36 -> 105420 | F36: 6 | G36: Serv | H36: 3289 | I36: =H36*F36 -> 19734 | J36: =I36+E36 -> 125154
A37: Equipo menor(LV Panelboards, LV TRs, etc) | F37: 1 | G37: Serv | H37: 85987 | I37: =H37*F37 -> 85987 | J37: =I37+E37 -> 85987
E38: =SUM(E27:E37) -> 3385602.5 | I38: =SUM(I27:I37) -> 552995.5
A39: Special Systems (Suministros) | C39: Pza
A40: Sistema de monitoreo de Infraestructura | B40: 1 | C40: Lte | D40: 105270 | E40: =D40*B40 -> 105270 | F40: 1 | G40: Serv | H40: 80604 | I40: =H40*F40 -> 80604 | J40: =I40+E40 -> 185874
A41: Cuarto Telecom MMR | B41: 2 | C41: Lte | D41: 20364.5 | E41: =D41*B41 -> 40729 | F41: 2 | G41: Serv | H41: 24889.5 | I41: =H41*F41 -> 49779 | J41: =I41+E41 -> 90508
A42: CCTV | B42: 1 | C42: Lte | D42: 35890 | E42: =D42*B42 -> 35890 | F42: 1 | G42: Serv | H42: 29364 | I42: =H42*F42 -> 29364 | J42: =I42+E42 -> 65254
A43: CA | B43: 1 | C43: Lte | D43: 25132 | E43: =D43*B43 -> 25132 | F43: 1 | G43: Serv | H43: 27226.5 | I43: =H43*F43 -> 27226.5 | J43: =I43+E43 -> 52358.5
A44: Vesda | B44: 1 | C44: Lte | D44: 159770 | E44: =D44*B44 -> 159770 | F44: 1 | G44: Serv | H44: 70484 | I44: =H44*F44 -> 70484 | J44: =I44+E44 -> 230254
A45: Sistema detección y extinción automático con Novec Áreas ( CPD Y UPS, A Y B) | B45: 1 | C45: Lte | D45: 151525 | E45: =D45*B45 -> 151525 | F45: 1 | G45: Serv | H45: 84349 | I45: =H45*F45 -> 84349 | J45: =I45+E45 -> 235874
...

Sheet network eq.
A1: Capa | B1: Equipo | C1: Modelo / Especificación | D1: Unidad | E1: Cantidad | F1: Costo Unitario USD | G1: Subtotal USD | H1: Tipo de Cambio | I1: Subtotal MXN | J1: Notas
A2: Leaf (AI Fabric) | B2: InfiniBand Switch | C2: NVIDIA Quantum HDR 200Gb/s (40p QSFP56) | D2: Switch | E2: 2 | F2: 120000 | G2: =E2*F2 -> 240000 | H2: 18.01 | I2: =G2*H2 -> 4322400 | J2: Leaf AI
A3: Spine (AI Fabric) | B3: InfiniBand Switch | C3: NVIDIA Quantum-2 NDR 400Gb/s | D3: Switch | E3: 1 | F3: 220000 | G3: =E3*F3 -> 220000 | H3: 18.01 | I3: =G3*H3 -> 3962200 | J3: Spine central
A4: NIC GPU | B4: Adaptador de red | C4: NVIDIA ConnectX-7 200Gb/s | D4: NIC | E4: 56 | F4: 1800 | G4: =E4*F4 -> 100800 | H4: 18.01 | I4: =G4*H4 -> 1815408 | J4: 8 NICs por rack
A5: Optics | B5: Transceiver QSFP56 | C5: 200Gb/s SR4/DR4 | D5: Unidad | E5: 60 | F5: 2000 | G5: =E5*F5 -> 120000 | H5: 18.01 | I5: =G5*H5 -> 2161200 | J5: Fabric
A6: Cabling | B6: DAC / AOC | C6: 200Gb/s | D6: Unidad | E6: 40 | F6: 800 | G6: =E6*F6 -> 32000 | H6: 18.01 | I6: =G6*H6 -> 576320 | J6: Intra-rack
A7: Mgmt Network | B7: Ethernet Switch | C7: 100GbE L3 | D7: Switch | E7: 2 | F7: 45000 | G7: =E7*F7 -> 90000 | H7: 18.01 | I7: =G7*H7 -> 1620900 | J7: OOB / BMS
A8: TOTAL | G8: =SUM(G2:G7) -> 802800 | I8: =SUM(I2:I7) -> 14458428
A11: Concepto | B11: USD
A12: 4× Routers WAN | B12: =120000*2 -> 240000
A13: 2× Firewalls | B13: 100000
A14: Ópticos / X-connect | B14: 25000
A15: Total Edge / Internet | B15: 245,000 USD
