Workbook
Name TC: [1]CAPEX!$D$3

Sheet Financing
B2: Entity | C2: Financing Type | D2: Description | E2: I/Y | F2: Comment
B3: Dell Financing Services | C3: Financial Lease | D3: Corporate guarantee | E3: 3-9% | F3: Cannot perform asset backed financing | G3: Under Review
B4: Dell Financing Services | C4: Pure Lease | D4: Corporate guarantee | E4: 3-9% | F4: Cannot perform asset backed financing | G4: Under Review
B5: Dell Financing Services | C5: Pay as you use | D5: Corporate guarantee | E5: 3-9% | F5: Cannot perform asset backed financing | G5: Under Review
B6: Dell Financing Services | C6: Simple Credit | D6: Corporate guarantee | E6: 3-9% | F6: Cannot perform asset backed financing | G6: Under Review
B7: Permian Labs | C7: Simple Credit | D7: Asset backed | E7: 10-15% | F7: For “on‑demand spec rental” (no contracted offtake, similar to Hydra Host month‑to‑month model), indicative all‑in cost of capital is about 10–15% at 70–80% LTV. Loan can be ammended (lower interest) once long term contract is signed Loan-to-value (LTV): 70–80% of hardware cost. Tenor and amortization: 3‑year term, straight‑line amortization to zero over the 3 years. Scope of collateral: USD.AI finances only servers and networking equipment (compute stack), not the modular data center shell or facility infrastructure. | G7: TSA SIGNED
B8: Trinity | C8: Simple Credit | D8: Corporate guarantee or asset backed | E8: 10-12% | F8: Cannot offer financing in Mexico | G8: NA
B9: VFI | C9: Different financing modalities | D9: Corporate guarantee | E9: NA | F9: Cannot offer financing in Mexico | G9: Under Review
B10: SMBC | C10: Simple Credit | D10: Asset backed | E10: TBD | F10: Information sent, awaiting response. Initial talks. | G10: Meeting 06/03/2026
B11: Chuck Leaver | C11: Simple Credit | D11: Asset backed | E11: 0.12 | F11: For “on‑demand spec rental” (no contracted offtake, similar to Hydra Host month‑to‑month model), indicative all‑in cost of capital is about 12% at 70–80% LTV. Loan-to-value (LTV): 70–80% of hardware cost. Tenor and amortization: 3‑year term, straight‑line amortization to zero over the 3 years. Scope of collateral: USD.AI finances only servers and networking equipment (compute stack), not the modular data center shell or facility infrastructure. | G11: On Hold
B12: Altum Capital | C12: Simple Credit | D12: Asset backed | E12: TBD | F12: Pending - Schedule kickoff call. | G12: On Hold
B13: Beel Capital | C13: Simple Credit | D13: Asset backed | E13: TBD | F13: Info sent, waiting for follow up | G13: On Hold
B14: Metaversal | C14: Bridge Financing | D14: Asset backed | E14: TBD | F14: Initial talks, waiting for NDA signature and then dive into due diligence. | G14: NDA Signature
B15: Corporate Guarantee | C15: Contractual | D15: AAA Backed | F15: Initial talks with Sabino Escobedo who will search out potential backing from World Bank | G15: Initial talks

Sheet Equity
B2: Entity | C2: Fund type | D2: Ticket size | E2: Comment
B3: Olayan Group | C3: Middle East family office | D3: US.$ 5-10MM
B4: ERA Funds | C4: AI oriented equity and/or debt | D4: US.$ 5-10MM | E4: Schedule intro call for Fermaca Digital Origins
B5: Phillipe Sourofim | C5: PE / VC | D5: US.$ 5-10MM | E5: Intro Calll

Sheet S&U
B2: Sources and Uses FDO
B4: Concept | C4: Unit | D4: Metric
B5: LTV GPUs | C5: % | D5: 0.8
B6: I/Y GPUs | C6: % | D6: 0.15
B7: Tenor GPUs | C7: yrs | D7: 3
B8: Monthly payment GPUs | C8: PMT | D8: =PMT(D6/12,D7*12,-D17) -> 1081558.2
B9: LTV DC CAPEX | C9: % | D9: 0.8
B10: I/Y DC CAPEX | C10: % | D10: 0.08
B11: Tenor DC CAPEX | C11: yrs | D11: 10
B12: Monthly payment DC CAPEX | C12: PMT | D12: =PMT(D10/12,D11*12,-D18) -> 39989.575
B13: DSRA | C13: months | D13: 0
B14: EPC Financing | C14: % | D14: 0.1
B16: Sources | C16: Description | D16: Amount | E16: % of Total | G16: Uses | H16: Description | I16: Amount | J16: % of Total
B17: Debt Financing GPUs | C17: Financing amount for GPUs | D17: =I17*D5 -> 31200000 | E17: =D17/$D$24 -> 0.67589422 | G17: GPUs | H17: Dell or Supermicro w/NVIDIA B300 (HPC Compute) | I17: 39000000 | J17: =I17/$I$43 -> 0.84486778
B18: Debt Financing DC CAPEX | C18: Financing amount for DC CAPEX | D18: =D9*I18 -> 3296000 | E18: =D18/$D$24 -> 0.071402159 | G18: AUXILIARY CAPEX | H18: Cooling, electrical, plumbing, telecom, etc. | I18: 4120000 | J18: =I18/$I$43 -> 0.089252699
B19: Fermaca Equity | C19: Equity from within | D19: 3000000 | E19: =D19/$D$24 -> 0.064989829 | G19: Backup Generation System (Generators) | H19: Aux DC CAPEX
B20: New Investor Equity | C20: New Investor needs | D20: =I43-D21-D19-D18-D17 -> 8497399.2 | E20: =D20/$D$24 -> 0.18408151 | G20: Automatic Transfer Switch (ATS) | H20: Aux DC CAPEX
B21: EPC Financing | C21: 10% EPC financing | D21: =D14*(I33+I34) -> 167670 | E21: =D21/$D$24 -> 0.0036322816 | G21: Main Transformer | H21: Aux DC CAPEX
B22: Bridge Financing (interim) | C22: Short-term GPU bridge (Metaversal) | D22: ='Bridge Financing'!D19 -> 27300000 | E22: =D22/$D$24 -> 0.59140745
G23: UPS | H23: Aux DC CAPEX
B24: Total Sources | D24: =SUM(D17:D21) -> 46161069 | E24: =SUM(E17:E21) -> 1 | G24: Battery Bank | H24: Aux DC CAPEX
G25: Medium Voltage Panel | H25: Aux DC CAPEX
C26: Check | D26: =D24=I43 -> TRUE | G26: Switchgear | H26: Aux DC CAPEX
G27: Modular Cabinet Cooling System (Chillers) | H27: Aux DC CAPEX
G28: Telecom | H28: Aux DC CAPEX
G29: Security | H29: Aux DC CAPEX
G30: DDC (Cabinets) | H30: Aux DC CAPEX
G31: Procurement & Construction Manager | H31: Aux DC CAPEX
G32: Non Financeable CAPEX | H32: Project development, engineering, construction, non detachable | I32: =SUM(I33:I38) -> 2562588 | J32: =I32/$I$43 -> 0.055514052
G33: Engineering | H33: Engineering | I33: 90000
G34: Construction | H34: FDO Construction | I34: 1586700
G35: Commissioning | H35: Tests | I35: 150000
G36: CFE Commitments | H36: CFE quote for capacity increase | I36: =(3870100+46400+1043900)/20 -> 248020
G37: Bcysa Feasibility & Development contract | H37: BCYSA Quote | I37: 250000 | L37: Contingency Calculation
G38: Bcysa Owners Engineer | H38: BCYSA Quote | I38: =0.04*(I18+I33+I34+I35) -> 237868 | L38: Contingency | M38: 0.07
G39: Permits and Studies | H39: Local permits and structural studies | I39: 10000 | J39: =I39/$I$43 -> 0.00021663276 | L39: Subtotal | M39: =(I18+I32+I39)*1 -> 6692588
G40: Contingency | H40: 7% contingency | I40: =M39*M38 -> 468481.16 | J40: =I40/$I$43 -> 0.010148837
G41: DSCA of 3 months | H41: Construction reserve account | I41: =D8*D13 -> 0 | J41: =I41/$I$43 -> 0
G43: Total Uses | I43: =I17+I18+I32+I39+I40+I41 -> 46161069 | J43: =SUM(J17,J18,J32,J39:J41) -> 1
H45: Check | I45: =I43=D24 -> TRUE

Sheet S&U (2)
B2: Sources and Uses FDO
B4: Concept | C4: Unit | D4: Metric
B5: LTV GPUs | C5: % | D5: 0.8
B6: I/Y GPUs | C6: % | D6: 0.15
B7: Tenor GPUs | C7: yrs | D7: 3
B8: Monthly payment GPUs | C8: PMT | D8: =PMT(D6/12,D7*12,-D17) -> 1049574.7
B9: LTV DC CAPEX | C9: % | D9: 0.8
B10: I/Y DC CAPEX | C10: % | D10: 0.08
B11: Tenor DC CAPEX | C11: yrs | D11: 10
B12: Monthly payment DC CAPEX | C12: PMT | D12: =PMT(D10/12,D11*12,-D18) -> 70551.74
B13: DSRA | C13: months | D13: 0
B14: EPC Financing | C14: % | D14: 0.1
B16: Sources | C16: Description | D16: Ammount | F16: Uses | G16: Description | H16: Ammount
B17: Debt Financing GPUs | C17: Financing ammount for GPUs | D17: =H17*D5 -> 30277361 | F17: GPUs | G17: Dell or Supermicro w/NVIDIA B300 (HPC Compute) | H17: =[1]Hoja1!E45 -> 37846701
B18: Debt Financing DC CAPEX | C18: Financing ammount for DC CAPEX | D18: =D9*H18 -> 5814978.9 | F18: AUXILIARY CAPEX | G18: Cooling, electrical, plumbing, telecom, etc. | H18: =SUM(H19:H30) -> 7268723.7
B19: Fermaca Equity | C19: Equity from within | D19: 3000000 | F19: SISTEMA DE GENERACIÓN DE RESPALDO (GENERADORES) | G19: Aux DC CAPEX | H19: =[1]Hoja1!E8 -> 933813.57
B20: New Investor Equity | C20: New Investor needs | D20: =H42-D21-D19-D18-D17 -> 8420506.4 | F20: INTERRUPTOR DE TRANSFERENCIA AUTOMÁTICA (ATS) | G20: Aux DC CAPEX | H20: =[1]Hoja1!E10 -> 192932.87
B21: EPC Financing | C21: 10% EPC financing | D21: =D14*(H32+H33) -> 90000 | F21: TRANSFORMADOR PRINCIPAL | G21: Aux DC CAPEX | H21: =[1]Hoja1!E12 -> 222740.82
F22: UPS | G22: Aux DC CAPEX | H22: =[1]Hoja1!E14 -> 1050171.8
B23: Total Sources | D23: =SUM(D17:D21) -> 47602846 | F23: BANCO DE BATERÍAS | G23: Aux DC CAPEX | H23: =[1]Hoja1!E16 -> 402506.94
F24: TABLERO DE MEDIA TENSIÓN | G24: Aux DC CAPEX | H24: =[1]Hoja1!E18 -> 168563.46
C25: Check | D25: =D23=H42 -> TRUE | F25: SWITCHGEAR | G25: Aux DC CAPEX | H25: =[1]Hoja1!E20 -> 544324.95
F26: SISTEMA DE REFRIGERACIÓN PARA LOS GABINETES MODULARES TIPO CONTENEDOR (CHILLERS) | G26: Aux DC CAPEX | H26: =[1]Hoja1!E21 -> 1565349.3
F27: Telecom | G27: Aux DC CAPEX | H27: =[1]Hoja1!E25 -> 460244.5
F28: SEGURIDAD | G28: Aux DC CAPEX | H28: =[1]Hoja1!E31 -> 303759.5
F29: DDC (Gabinetes) | G29: Aux DC CAPEX | H29: =[1]Hoja1!E34 -> 1218276.8
F30: Procura y Obra Gestor | G30: Aux DC CAPEX | H30: =4120784/20 -> 206039.2
F31: Non Fineaceable CAPEX | G31: Project development, engineering, construction, non detachable | H31: =SUM(H32:H37) -> 1839168.9
F32: Engineering | G32: Engineering | H32: 300000
F33: Construction | G33: FDO Construction | H33: 600000
F34: Commissioning | G34: Tests | H34: 110000
F35: CFE Commitments | G35: CFE quote for capacity increase | H35: =(3870100+46400+1043900)/20 -> 248020
F36: Bcysa Feasibility & Development contract | G36: BCYSA Quote | H36: 250000
F37: Bcysa Owners Engineer | G37: BCYSA Quote | H37: =0.04*(H18+H32+H33+H34) -> 331148.95 | J37: Contingency | K37: 0.07
F38: Permits and Studies | G38: Local permits and structural studies | H38: 10000 | J38: Subtotal | K38: =(H18+H31+H38)*1 -> 9117892.6
F39: Contingency | G39: 7% contigency | H39: =K38*K37 -> 638252.48
F40: DSCA of 3 months | G40: Construction reserve account | H40: =D8*D13 -> 0
F42: Total Uses | H42: =H17+H18+H31+H38+H39+H40 -> 47602846
G44: Check | H44: =H42=D23 -> TRUE

Sheet Bridge Financing
B2: Bridge Financing — GPU Procurement
B4: Assumptions | C4: Unit | D4: Metric
B5: GPU CAPEX (from S&U) | C5: $ | D5: ='S&U'!I17 -> 39000000
B6: Bridge LTV | C6: % | D6: 0.7
B7: Bridge Interest Rate (annual) | C7: % | D7: 0.1
B8: Bridge Tenor | C8: months | D8: 6
B9: Origination Fee | C9: % | D9: 0.01
B10: Collateral | D10: GPU Hardware (Asset Backed)
B11: Lender | D11: Metaversal (TBD)
B13: Permanent Financing Terms (S&U) | C13: Unit | D13: Metric
B14: Permanent LTV (GPUs) | C14: % | D14: ='S&U'!D5 -> 0.8
B15: Permanent I/Y (GPUs) | C15: % | D15: ='S&U'!D6 -> 0.15
B16: Permanent Tenor (GPUs) | C16: yrs | D16: ='S&U'!D7 -> 3
B18: Bridge Loan Summary | D18: Amount
B19: Bridge Loan Amount | D19: =D5*D6 -> 27300000
B20: Origination Fee ($) | D20: =D19*D9 -> 273000
B21: Monthly Interest Rate | D21: =D7/12 -> 0.0083333333
B22: Monthly Interest Payment | D22: =D19*D21 -> 227500
B23: Total Interest Paid (6 months) | D23: =D22*D8 -> 1365000
B24: Total Cost of Bridge | D24: =D20+D23 -> 1638000
B25: Cost as % of Loan | D25: =D24/D19 -> 0.06
B26: Net Proceeds (after fee) | D26: =D19-D20 -> 27027000
B28: Interest-Only Schedule (Bullet at Maturity) | C28: Opening Balance | D28: Interest | E28: Principal | F28: Payment | G28: Closing Balance
B29: Month 1 | C29: =$D$19 -> 27300000 | D29: =C29*$D$21 -> 227500 | E29: 0 | F29: =D29+E29 -> 227500 | G29: =C29-E29 -> 27300000
B30: Month 2 | C30: =G29 -> 27300000 | D30: =C30*$D$21 -> 227500 | E30: 0 | F30: =D30+E30 -> 227500 | G30: =C30-E30 -> 27300000
B31: Month 3 | C31: =G30 -> 27300000 | D31: =C31*$D$21 -> 227500 | E31: 0 | F31: =D31+E31 -> 227500 | G31: =C31-E31 -> 27300000
B32: Month 4 | C32: =G31 -> 27300000 | D32: =C32*$D$21 -> 227500 | E32: 0 | F32: =D32+E32 -> 227500 | G32: =C32-E32 -> 27300000
B33: Month 5 | C33: =G32 -> 27300000 | D33: =C33*$D$21 -> 227500 | E33: 0 | F33: =D33+E33 -> 227500 | G33: =C33-E33 -> 27300000
B34: Month 6 | C34: =G33 -> 27300000 | D34: =C34*$D$21 -> 227500 | E34: =C34 -> 27300000 | F34: =D34+E34 -> 27527500 | G34: =C34-E34 -> 0
B35: Total | D35: =SUM(D29:D34) -> 1365000 | E35: =SUM(E29:E34) -> 27300000 | F35: =SUM(F29:F34) -> 28665000
B37: Refinancing Summary (Month 6 → Permanent) | D37: Amount
B38: Bridge Loan Repaid at Maturity | D38: =D19 -> 27300000
B39: Permanent GPU Debt Facility (replaces bridge) | D39: ='S&U'!D17 -> 31200000
B40: Permanent Monthly Payment (GPUs) | D40: ='S&U'!D8 -> 1081558.2
B41: Excess from Permanent over Bridge | D41: =D39-D19 -> 3900000
B43: Bridge vs. Permanent Comparison | C43: Bridge | D43: Permanent
B44: Loan Amount | C44: =D19 -> 27300000 | D44: =D39 -> 31200000
B45: Interest Rate | C45: =D7 -> 0.1 | D45: =D15 -> 0.15
B46: Tenor | C46: =D8&" months" -> 6 months | D46: =D16&" years" -> 3 years
B47: LTV | C47: =D6 -> 0.7 | D47: =D14 -> 0.8
...
