Workbook

Sheet Invoice Reconciliation (Raw)
A1: Contract Start Date | B1: Term | C1: Term_Fixed | D1: GPU Type | E1: GPUs/Quant | F1: Buyer GPU/ Hr | G1: Supplier GPU/ Hr | H1: Spread
A2: 45793 | B2: 6mo | C2: =_xlfn.IFNA(VLOOKUP($B2,ref!$B$2:$C$34,2,FALSE),"NA") -> 6 Month | D2: H100 | E2: 1024 | F2: 2.66 | G2: 2.51 | H2: =1-(G2/F2) -> 0.056390977 | J2: =AVERAGE(E2:E143) -> 294.6338
A3: 45793 | B3: 6mo | C3: =_xlfn.IFNA(VLOOKUP($B3,ref!$B$2:$C$34,2,FALSE),"NA") -> 6 Month | D3: H100 | E3: 1024 | F3: 2.66 | G3: 2.51 | H3: =1-(G3/F3) -> 0.056390977
A4: 45793 | B4: 6mo | C4: =_xlfn.IFNA(VLOOKUP($B4,ref!$B$2:$C$34,2,FALSE),"NA") -> 6 Month | D4: H100 | E4: 1024 | F4: 2.66 | G4: 2.51 | H4: =1-(G4/F4) -> 0.056390977
A5: 45793 | B5: 6mo | C5: =_xlfn.IFNA(VLOOKUP($B5,ref!$B$2:$C$34,2,FALSE),"NA") -> 6 Month | D5: H100 | E5: 1024 | F5: 2.66 | G5: 2.51 | H5: =1-(G5/F5) -> 0.056390977
A6: 45793 | B6: 6mo | C6: =_xlfn.IFNA(VLOOKUP($B6,ref!$B$2:$C$34,2,FALSE),"NA") -> 6 Month | D6: H100 | E6: 1024 | F6: 2.66 | G6: 2.51 | H6: =1-(G6/F6) -> 0.056390977
A7: 45793 | B7: 12 mo | C7: =_xlfn.IFNA(VLOOKUP($B7,ref!$B$2:$C$34,2,FALSE),"NA") -> 12 Month | D7: H100 | E7: 1024 | F7: 2.66 | G7: 2.51 | H7: =1-(G7/F7) -> 0.056390977
A8: 45764 | C8: =_xlfn.IFNA(VLOOKUP($B8,ref!$B$2:$C$34,2,FALSE),"NA") -> NA | D8: H100 | E8: 1024 | F8: 0.15 | H8: =1-(G8/F8) -> 1
A9: 45733 | B9: 12mo | C9: =_xlfn.IFNA(VLOOKUP($B9,ref!$B$2:$C$34,2,FALSE),"NA") -> 12 Month | D9: H100 | E9: 1024 | F9: 2.66 | G9: 2.51 | H9: =1-(G9/F9) -> 0.056390977
A10: 45705 | B10: 12mo | C10: =_xlfn.IFNA(VLOOKUP($B10,ref!$B$2:$C$34,2,FALSE),"NA") -> 12 Month | D10: H100 | E10: 1024 | F10: 2.66 | G10: 2.51 | H10: =1-(G10/F10) -> 0.056390977
A11: 45684 | B11: 12mo | C11: =_xlfn.IFNA(VLOOKUP($B11,ref!$B$2:$C$34,2,FALSE),"NA") -> 12 Month | D11: H100 | E11: 1024 | F11: 2.66 | G11: 2.51 | H11: =1-(G11/F11) -> 0.056390977
A12: 45839 | B12: 24mo | C12: =_xlfn.IFNA(VLOOKUP($B12,ref!$B$2:$C$34,2,FALSE),"NA") -> 24 Month | D12: H100 | E12: 1008 | F12: 2.12 | G12: 2.12 | H12: =1-(G12/F12) -> 0
A13: 45839 | B13: 24mo | C13: =_xlfn.IFNA(VLOOKUP($B13,ref!$B$2:$C$34,2,FALSE),"NA") -> 24 Month | D13: H100 | E13: 1008 | F13: 2.61 | G13: 2.53 | H13: =1-(G13/F13) -> 0.030651341
A14: 45839 | B14: 24mo | C14: =_xlfn.IFNA(VLOOKUP($B14,ref!$B$2:$C$34,2,FALSE),"NA") -> 24 Month | D14: H100 | E14: 1008 | F14: 2.12 | G14: 2.12 | H14: =1-(G14/F14) -> 0
A15: 45839 | B15: 24mo | C15: =_xlfn.IFNA(VLOOKUP($B15,ref!$B$2:$C$34,2,FALSE),"NA") -> 24 Month | D15: H100 | E15: 1008 | F15: 2.61 | G15: 2.53 | H15: =1-(G15/F15) -> 0.030651341
A16: 45839 | B16: 24mo | C16: =_xlfn.IFNA(VLOOKUP($B16,ref!$B$2:$C$34,2,FALSE),"NA") -> 24 Month | D16: H100 | E16: 1008 | F16: 2.61 | G16: 2.53 | H16: =1-(G16/F16) -> 0.030651341
A17: 45839 | B17: 24mo | C17: =_xlfn.IFNA(VLOOKUP($B17,ref!$B$2:$C$34,2,FALSE),"NA") -> 24 Month | D17: H100 | E17: 1008 | F17: 2.61 | G17: 2.53 | H17: =1-(G17/F17) -> 0.030651341
A18: 45839 | B18: 24mo | C18: =_xlfn.IFNA(VLOOKUP($B18,ref!$B$2:$C$34,2,FALSE),"NA") -> 24 Month | D18: H100 | E18: 1008 | F18: 2.61 | G18: 2.53 | H18: =1-(G18/F18) -> 0.030651341
A19: 45839 | B19: 24mo | C19: =_xlfn.IFNA(VLOOKUP($B19,ref!$B$2:$C$34,2,FALSE),"NA") -> 24 Month | D19: H100 | E19: 1008 | F19: 2.61 | G19: 2.53 | H19: =1-(G19/F19) -> 0.030651341
A20: 45778 | C20: =_xlfn.IFNA(VLOOKUP($B20,ref!$B$2:$C$34,2,FALSE),"NA") -> NA | D20: H100 | E20: 1008 | F20: 2.61 | G20: 2.503 | H20: =1-(G20/F20) -> 0.040996169
A21: 45658 | C21: =_xlfn.IFNA(VLOOKUP($B21,ref!$B$2:$C$34,2,FALSE),"NA") -> NA | D21: H100 | E21: 1008 | F21: 2.61 | G21: 2.503 | H21: =1-(G21/F21) -> 0.040996169
A22: 45658 | B22: 24mo | C22: =_xlfn.IFNA(VLOOKUP($B22,ref!$B$2:$C$34,2,FALSE),"NA") -> 24 Month | D22: H100 | E22: 1008 | F22: 2.61 | G22: 2.503 | H22: =1-(G22/F22) -> 0.040996169
A23: 45991 | C23: =_xlfn.IFNA(VLOOKUP($B23,ref!$B$2:$C$34,2,FALSE),"NA") -> NA | D23: H100 | E23: 512 | F23: 1.3 | G23: 1.25 | H23: =1-(G23/F23) -> 0.038461538
A24: 45808 | B24: 1mo | C24: =_xlfn.IFNA(VLOOKUP($B24,ref!$B$2:$C$34,2,FALSE),"NA") -> 1 Month | D24: H100 | E24: 512 | F24: 1.3 | G24: 1.25 | H24: =1-(G24/F24) -> 0.038461538
A25: 45778 | B25: 12mo | C25: =_xlfn.IFNA(VLOOKUP($B25,ref!$B$2:$C$34,2,FALSE),"NA") -> 12 Month | D25: 4090 | E25: 390 | F25: 0.32 | G25: 0.26 | H25: =1-(G25/F25) -> 0.1875
A26: 45778 | B26: 12mo | C26: =_xlfn.IFNA(VLOOKUP($B26,ref!$B$2:$C$34,2,FALSE),"NA") -> 12 Month | D26: 4090 | E26: 390 | F26: 0.32 | G26: 0.26 | H26: =1-(G26/F26) -> 0.1875
A27: 45778 | B27: 12mo | C27: =_xlfn.IFNA(VLOOKUP($B27,ref!$B$2:$C$34,2,FALSE),"NA") -> 12 Month | D27: 4090 | E27: 390 | F27: 0.32 | G27: 0.26 | H27: =1-(G27/F27) -> 0.1875
A28: 45689 | B28: m2m | C28: =_xlfn.IFNA(VLOOKUP($B28,ref!$B$2:$C$34,2,FALSE),"NA") -> Spot | D28: 4090 | E28: 390 | F28: 0.32 | G28: 0.26 | H28: =1-(G28/F28) -> 0.1875
A29: 45689 | B29: m2m | C29: =_xlfn.IFNA(VLOOKUP($B29,ref!$B$2:$C$34,2,FALSE),"NA") -> Spot | D29: 4090 | E29: 390 | F29: 0.32 | G29: 0.26 | H29: =1-(G29/F29) -> 0.1875
A30: 45689 | C30: =_xlfn.IFNA(VLOOKUP($B30,ref!$B$2:$C$34,2,FALSE),"NA") -> NA | D30: 4090 | E30: 390 | F30: 0.32 | G30: 0.26 | H30: =1-(G30/F30) -> 0.1875
A31: 45799 | B31: 3mo | C31: =_xlfn.IFNA(VLOOKUP($B31,ref!$B$2:$C$34,2,FALSE),"NA") -> 3 Month | D31: H200 | E31: 384 | F31: 1.75 | G31: 1.5 | H31: =1-(G31/F31) -> 0.14285714
A32: 46066 | B32: 6mo | C32: =_xlfn.IFNA(VLOOKUP($B32,ref!$B$2:$C$34,2,FALSE),"NA") -> 6 Month | D32: H100 | E32: 352 | F32: 1.42 | G32: 1.25 | H32: =1-(G32/F32) -> 0.11971831
A33: 46044 | B33: 1mo | C33: =_xlfn.IFNA(VLOOKUP($B33,ref!$B$2:$C$34,2,FALSE),"NA") -> 1 Month | D33: B200 | E33: 336 | F33: 1.63 | G33: 1.315 | H33: =1-(G33/F33) -> 0.19325153
A34: 46034 | B34: 43739719591 | C34: =_xlfn.IFNA(VLOOKUP($B34,ref!$B$2:$C$34,2,FALSE),"NA") -> Misc | D34: B200 | E34: 256 | F34: 2.8 | G34: 2.6 | H34: =1-(G34/F34) -> 0.071428571
A35: 46034 | B35: 24mo | C35: =_xlfn.IFNA(VLOOKUP($B35,ref!$B$2:$C$34,2,FALSE),"NA") -> 24 Month | D35: B200 | E35: 256 | F35: 2.8 | G35: 2.6 | H35: =1-(G35/F35) -> 0.071428571
A36: 45767 | B36: 3mo | C36: =_xlfn.IFNA(VLOOKUP($B36,ref!$B$2:$C$34,2,FALSE),"NA") -> 3 Month | D36: H200 | E36: 256 | F36: 2.35 | G36: 2.1 | H36: =1-(G36/F36) -> 0.10638298
A37: 45767 | B37: 3mo | C37: =_xlfn.IFNA(VLOOKUP($B37,ref!$B$2:$C$34,2,FALSE),"NA") -> 3 Month | E37: 256 | F37: 0.25 | H37: =1-(G37/F37) -> 1
A38: 45723 | C38: =_xlfn.IFNA(VLOOKUP($B38,ref!$B$2:$C$34,2,FALSE),"NA") -> NA | D38: H200 | E38: 256 | F38: 2.1 | G38: 2.1 | H38: =1-(G38/F38) -> 0
A39: 45723 | B39: 3mo | C39: =_xlfn.IFNA(VLOOKUP($B39,ref!$B$2:$C$34,2,FALSE),"NA") -> 3 Month | D39: H200 | E39: 256 | F39: 2.1 | G39: 2.1 | H39: =1-(G39/F39) -> 0
A40: 45905 | B40: wk | C40: =_xlfn.IFNA(VLOOKUP($B40,ref!$B$2:$C$34,2,FALSE),"NA") -> Spot | D40: H200 | E40: 224 | F40: 1.75 | G40: 1.6 | H40: =1-(G40/F40) -> 0.085714286
...

Sheet Pivot
A3: Row Labels | B3: Count of Term_Fixed | C3: Average of Supplier GPU/ Hr | D3: Average of GPUs/Quant
A4: 1 Month | B4: 167 | C4: 167 | D4: 167
A5: 3090 | B5: 13 | C5: 0.23230769 | D5: 20.307692
A6: 4090 | B6: 2 | C6: 0.355 | D6: 16
A7: 5090 | B7: 4 | C7: 0.51 | D7: 40
A8: A100 | B8: 18 | C8: 1.1766667 | D8: 12
A9: A6000 Ampere | B9: 1 | C9: 0.52 | D9: 8
A10: B200 | B10: 16 | C10: 3.0296875 | D10: 50.625
A11: CPU | B11: 8 | C11: 144.22275 | D11: 4.125
A12: GH200 | B12: 1 | C12: 1.8 | D12: 2
A13: H100 | B13: 33 | C13: 1.7715152 | D13: 45
A14: H200 | B14: 54 | C14: 1.9509259 | D14: 55.240741
A15: L40S | B15: 9 | C15: 0.76333333 | D15: 86.222222
A16: RTX Pro 6000 | B16: 1 | C16: 1.2 | D16: 24
A17: Storage | B17: 1 | C17: 40 | D17: 25
A18: (blank) | B18: 6 | C18: 1.4816667 | D18: 34.666667
A19: 12 Month | B19: 102 | C19: 98 | D19: 102
A20: 4090 | B20: 23 | C20: 0.27826087 | D20: 83.304348
A21: 5090 | B21: 2 | C21: 0.45 | D21: 8
A22: A100 | B22: 8 | C22: 1.1625 | D22: 38
A23: A100 40g | B23: 4 | D23: 8
A24: A100 80g | B24: 9 | C24: 0.95 | D24: 8
A25: A6000 | B25: 1 | C25: 0.38 | D25: 8
A26: B200 | B26: 7 | C26: 3.35 | D26: 30.857143
A27: H100 | B27: 35 | C27: 1.9788571 | D27: 139.42857
A28: H200 | B28: 10 | C28: 2.085 | D28: 9.6
A29: L40S | B29: 3 | C29: 0.87 | D29: 80
A30: 2 Month | B30: 3 | C30: 3 | D30: 3
A31: H200 | B31: 3 | C31: 1.7 | D31: 8
A32: 20 Month | B32: 7 | C32: 7 | D32: 7
A33: H200 | B33: 7 | C33: 2.55 | D33: 32
A34: 24 Month | B34: 10 | C34: 10 | D34: 10
A35: B200 | B35: 1 | C35: 2.6 | D35: 256
... A37: 3 Month | B37: 83 | C37: 82 | D37: 83
A38: 4090 | B38: 4 | C38: 0.508 | D38: 200
A39: 5090 | B39: 3 | C39: 0.44 | D39: 112
A40: A100 | B40: 5 | C40: 0.93 | D40: 8
A41: A100 80g PCIE | B41: 1 | C41: 1.19 | D41: 8
A42: B200 | B42: 9 | C42: 3.3166667 | D42: 50.666667
A43: CPU | B43: 4 | C43: 562.6575 | D43: 3
...

Sheet ref
B2: Term (Original) | C2: Term (Fixed)
B3: 43739719591 | C3: Misc
B4: 0.91mo | C4: Spot
B5: 0mo | C5: Spot
B6: 12 mo | C6: 12 Month
B7: 12mo | C7: 12 Month
B8: 1d | C8: Spot
B9: 1mo | C9: 1 Month
B10: 20mo | C10: 20 Month
B11: 24hr | C11: Spot
B12: 24mo | C12: 24 Month
B13: 2mo | C13: 2 Month
B14: 2w test | C14: Misc
B15: 3mo | C15: 3 Month
... B34: wk | C34: Spot

Sheet Price Evolution
A1: GPU Price Evolution — Avg Buyer Rate ($/GPU/Hr) | F1: Avg Supplier Rate ($/GPU/Hr)
A3: Month | B3: H100 | C3: H200 | D3: B200 | F3: Month | G3: H100 | H3: H200 | I3: B200
A4: 45597 | C4: 2.6 | F4: 45597 | H4: 2.4
A5: 45658 | B5: 2.34 | C5: 3.09 | F5: 45658 | G5: 2.16 | H5: 2.7
A6: 45689 | B6: 2.36 | C6: 2.98 | F6: 45689 | G6: 2.17 | H6: 2.59
A7: 45717 | B7: 2.14 | C7: 3.04 | F7: 45717 | G7: 1.99 | H7: 2.66
A8: 45748 | B8: 2.41 | C8: 3 | F8: 45748 | G8: 2.23 | H8: 2.61
A9: 45778 | B9: 2.12 | C9: 2.78 | F9: 45778 | G9: 2.03 | H9: 2.27
A10: 45809 | B10: 2.41 | C10: 2.46 | F10: 45809 | G10: 2.28 | H10: 2.2
A11: 45839 | B11: 2.48 | C11: 2.58 | D11: 3.59 | F11: 45839 | G11: 2.32 | H11: 2.41 | I11: 3.4
A12: 45870 | C12: 1.83 | D12: 3.5 | F12: 45870 | H12: 1.73 | I12: 3.14
A13: 45901 | B13: 1.65 | C13: 1.86 | D13: 3.65 | F13: 45901 | G13: 1.41 | H13: 1.65 | I13: 3.3
A14: 45931 | C14: 1.74 | D14: 3.5 | F14: 45931 | H14: 1.55 | I14: 3.34
A15: 45962 | B15: 1.21 | C15: 1.6 | D15: 3 | F15: 45962 | G15: 1.08 | H15: 1.42 | I15: 2.81
A16: 45992 | B16: 1.36 | C16: 2.04 | D16: 3.02 | F16: 45992 | G16: 1.25 | H16: 1.86 | I16: 2.87
A17: 46023 | B17: 1.46 | C17: 2.11 | D17: 3.01 | F17: 46023 | G17: 1.28 | H17: 1.9 | I17: 2.83
A18: 46054 | B18: 1.42 | D18: 3.98 | F18: 46054 | G18: 1.25 | I18: 3.55
A21: Monthly Deal Count
A22: Month | B22: H100 | C22: H200 | D22: B200
A23: 45597 | B23: 0 | C23: 1 | D23: 0
A24: 45658 | B24: 27 | C24: 18 | D24: 0
A25: 45689 | B25: 16 | C25: 56 | D25: 0
A26: 45717 | B26: 4 | C26: 40 | D26: 0
A27: 45748 | B27: 11 | C27: 172 | D27: 0
A28: 45778 | B28: 46 | C28: 92 | D28: 0
A29: 45809 | B29: 4 | C29: 43 | D29: 0
A30: 45839 | B30: 21 | C30: 23 | D30: 7
A31: 45870 | B31: 0 | C31: 62 | D31: 8
A32: 45901 | B32: 3 | C32: 29 | D32: 20
A33: 45931 | B33: 0 | C33: 18 | D33: 2
A34: 45962 | B34: 7 | C34: 27 | D34: 53
... A37: 46054 | B37: 3 | C37: 0 | D37: 13
